Workbook

Sheet Dashboard
B2: YEARS | F2: UASM Research Seminar Statistics | U2: YEARS
U3: 2025
U4: 2024

Sheet Tablas Reporte
F2: =IF(Dashboard!$B$2=2025,"2025 DATA",IF(Dashboard!$B$2=2024,"2024 DATA","HISTORICAL DATA")) -> HISTORICAL DATA
B4: UASM Seminars attendance 2024-2025 | F4: Seminars | I4: Speaker | L4: Participants
B5: Seminar | C5: Speaker | D5: # Total participants | F5: Seminar Modality | G5: # | I5: Origin of University | J5: # | L5: Seminar Attendance | M5: #
B6: Visiting Scholars Seminar Series | F6: On-Campus | G6: =IF(Dashboard!$B$2=2025,COUNTIFS(Seminarios[Modalidad],'Tablas Reporte'!F6,Seminarios[Año],2025),IF(Dashboard!$B$2=2024,COUNTIFS(Seminarios[Modalidad],'Tablas Reporte'!F6,Seminarios[Año],2024),COUNTIFS(Seminarios[Modalidad],'Tablas Reporte'!F6))) -> 20 | I6: Europe | J6: =IF(Dashboard!$B$2=2025,COUNTIFS(Conferencistas[Ubicación],'Tablas Reporte'!I6,Conferencistas[Año],2025),IF(Dashboard!$B$2=2024,COUNTIFS(Conferencistas[Ubicación],'Tablas Reporte'!I6,Conferencistas[Año],2024),COUNTIFS(Conferencistas[Ubicación],'Tablas Reporte'!I6))) -> 24 | L6: On-Campus | M6: =IF(Dashboard!$B$2=2025,COUNTIFS(Participantes[Modalidad],'Tablas Reporte'!L6,Participantes[Año],2025),IF(Dashboard!$B$2=2024,COUNTIFS(Participantes[Modalidad],'Tablas Reporte'!L6,Participantes[Año],2024),COUNTIFS(Participantes[Modalidad],'Tablas Reporte'!L6))) -> 540
B7: Visiting Scholars 1 | C7: Niels Van Quaquebeke | D7: =COUNTIFS(Participantes[Seminario al que asistió],'Tablas Reporte'!B7) -> 17 | F7: Online | G7: =IF(Dashboard!$B$2=2025,COUNTIFS(Seminarios[Modalidad],'Tablas Reporte'!F7,Seminarios[Año],2025),IF(Dashboard!$B$2=2024,COUNTIFS(Seminarios[Modalidad],'Tablas Reporte'!F7,Seminarios[Año],2024),COUNTIFS(Seminarios[Modalidad],'Tablas Reporte'!F7))) -> 16 | I7: North America | J7: =IF(Dashboard!$B$2=2025,COUNTIFS(Conferencistas[Ubicación],'Tablas Reporte'!I7,Conferencistas[Año],2025),IF(Dashboard!$B$2=2024,COUNTIFS(Conferencistas[Ubicación],'Tablas Reporte'!I7,Conferencistas[Año],2024),COUNTIFS(Conferencistas[Ubicación],'Tablas Reporte'!I7))) -> 16 | L7: Online | M7: =IF(Dashboard!$B$2=2025,COUNTIFS(Participantes[Modalidad],'Tablas Reporte'!L7,Participantes[Año],2025),IF(Dashboard!$B$2=2024,COUNTIFS(Participantes[Modalidad],'Tablas Reporte'!L7,Participantes[Año],2024),COUNTIFS(Participantes[Modalidad],'Tablas Reporte'!L7))+18) -> 474
B8: Visiting Scholars 2 | C8: Bryan Boots | D8: =COUNTIFS(Participantes[Seminario al que asistió],'Tablas Reporte'!B8) -> 22 | F8: Hybrid | G8: =IF(Dashboard!$B$2=2025,COUNTIFS(Seminarios[Modalidad],'Tablas Reporte'!F8,Seminarios[Año],2025),IF(Dashboard!$B$2=2024,COUNTIFS(Seminarios[Modalidad],'Tablas Reporte'!F8,Seminarios[Año],2024),COUNTIFS(Seminarios[Modalidad],'Tablas Reporte'!F8))) -> 9 | I8: South America | J8: =IF(Dashboard!$B$2=2025,COUNTIFS(Conferencistas[Ubicación],'Tablas Reporte'!I8,Conferencistas[Año],2025),IF(Dashboard!$B$2=2024,COUNTIFS(Conferencistas[Ubicación],'Tablas Reporte'!I8,Conferencistas[Año],2024),COUNTIFS(Conferencistas[Ubicación],'Tablas Reporte'!I8))) -> 9 | L8: Presencial fuera de Uniades | M8: =IF(Dashboard!$B$2=2025,0,IF(Dashboard!$B$2=2024,205,205)) -> 205
B9: Visiting Scholars 3 | C9: Spencer Ross | D9: =COUNTIFS(Participantes[Seminario al que asistió],'Tablas Reporte'!B9) -> 19 | F9: Total | G9: =SUM(G6:G8) -> 45 | I9: Oceania | J9: =IF(Dashboard!$B$2=2025,COUNTIFS(Conferencistas[Ubicación],'Tablas Reporte'!I9,Conferencistas[Año],2025),IF(Dashboard!$B$2=2024,COUNTIFS(Conferencistas[Ubicación],'Tablas Reporte'!I9,Conferencistas[Año],2024),COUNTIFS(Conferencistas[Ubicación],'Tablas Reporte'!I9))) -> 3 | L9: Total | M9: =SUM(M6:M8) -> 1219
B10: Visiting Scholars 4 | C10: Christiane Schwieren | D10: =COUNTIFS(Participantes[Seminario al que asistió],'Tablas Reporte'!B10) -> 13 | I10: Asia | J10: =IF(Dashboard!$B$2=2025,COUNTIFS(Conferencistas[Ubicación],'Tablas Reporte'!I10,Conferencistas[Año],2025),IF(Dashboard!$B$2=2024,COUNTIFS(Conferencistas[Ubicación],'Tablas Reporte'!I10,Conferencistas[Año],2024),COUNTIFS(Conferencistas[Ubicación],'Tablas Reporte'!I10))) -> 0
B11: Visiting Scholars 5 | C11: Barbara Culiberg | D11: =COUNTIFS(Participantes[Seminario al que asistió],'Tablas Reporte'!B11) -> 13 | F11: Seminar Category | G11: # | I11: Total | J11: =SUM(J6:J10) -> 52 | L11: Participants by Gender | M11: #
B12: Visiting Scholars 6 | C12: Janina Grabs y Rita Motta | D12: =COUNTIFS(Participantes[Seminario al que asistió],'Tablas Reporte'!B12) -> 28 | F12: Visiting Scholars Seminar Series | G12: =IF(Dashboard!$B$2=2025,COUNTIFS(Seminarios[Categoría],'Tablas Reporte'!F12,Seminarios[Año],2025),IF(Dashboard!$B$2=2024,COUNTIFS(Seminarios[Categoría],'Tablas Reporte'!F12,Seminarios[Año],2024),COUNTIFS(Seminarios[Categoría],'Tablas Reporte'!F12))) -> 13 | L12: Female | M12: =IF(Dashboard!$B$2=2025,COUNTIFS(Participantes[Género],"F",Participantes[Año],2025),IF(Dashboard!$B$2=2024,COUNTIFS(Participantes[Género],"F",Participantes[Año],2024),COUNTIFS(Participantes[Género],"F"))) -> 325
B13: Visiting Scholars 7 | C13: Lourdes Casanova | D13: =COUNTIFS(Participantes[Seminario al que asistió],'Tablas Reporte'!B13) -> 34 | F13: Ágora | G13: =IF(Dashboard!$B$2=2025,COUNTIFS(Seminarios[Categoría],'Tablas Reporte'!F13,Seminarios[Año],2025),IF(Dashboard!$B$2=2024,COUNTIFS(Seminarios[Categoría],'Tablas Reporte'!F13,Seminarios[Año],2024),COUNTIFS(Seminarios[Categoría],'Tablas Reporte'!F13))) -> 9 | I13: Speakers by gender | J13: # | L13: Male | M13: =IF(Dashboard!$B$2=2025,COUNTIFS(Participantes[Género],"M",Participantes[Año],2025),IF(Dashboard!$B$2=2024,COUNTIFS(Participantes[Género],"M",Participantes[Año],2024),COUNTIFS(Participantes[Género],"M"))) -> 626
B14: Visiting Scholars 8 | C14: Steven Kilroy | D14: =COUNTIFS(Participantes[Seminario al que asistió],'Tablas Reporte'!B14) -> 11 | F14: GHE | G14: =IF(Dashboard!$B$2=2025,COUNTIFS(Seminarios[Categoría],'Tablas Reporte'!F14,Seminarios[Año],2025),IF(Dashboard!$B$2=2024,COUNTIFS(Seminarios[Categoría],'Tablas Reporte'!F14,Seminarios[Año],2024),COUNTIFS(Seminarios[Categoría],'Tablas Reporte'!F14))) -> 6 | I14: Female | J14: =IF(Dashboard!$B$2=2025,COUNTIFS(Conferencistas[Genero],'Tablas Reporte'!I14,Conferencistas[Año],2025),IF(Dashboard!$B$2=2024,COUNTIFS(Conferencistas[Genero],'Tablas Reporte'!I14,Conferencistas[Año],2024),COUNTIFS(Conferencistas[Genero],'Tablas Reporte'!I14))) -> 17 | L14: NA | M14: =IF(Dashboard!$B$2=2025,COUNTIFS(Participantes[Género],"NA",Participantes[Año],2025),IF(Dashboard!$B$2=2024,COUNTIFS(Participantes[Género],"NA",Participantes[Año],2024),COUNTIFS(Participantes[Género],"NA"))+223) -> 268
B15: Visiting Scholars 9 | C15: Yimin Cheng | D15: =COUNTIFS(Participantes[Seminario al que asistió],'Tablas Reporte'!B15) -> 18 | F15: Recruitment research seminars | G15: =IF(Dashboard!$B$2=2025,COUNTIFS(Seminarios[Categoría],'Tablas Reporte'!F15,Seminarios[Año],2025),IF(Dashboard!$B$2=2024,COUNTIFS(Seminarios[Categoría],'Tablas Reporte'!F15,Seminarios[Año],2024),COUNTIFS(Seminarios[Categoría],'Tablas Reporte'!F15))) -> 16 | I15: Male | J15: =IF(Dashboard!$B$2=2025,COUNTIFS(Conferencistas[Genero],'Tablas Reporte'!I15,Conferencistas[Año],2025),IF(Dashboard!$B$2=2024,COUNTIFS(Conferencistas[Genero],'Tablas Reporte'!I15,Conferencistas[Año],2024),COUNTIFS(Conferencistas[Genero],'Tablas Reporte'!I15))) -> 35 | L15: Total | M15: =SUM(M12:M14) -> 1219
B16: Visiting Scholars 10 | C16: Suresh Sethi | D16: =COUNTIFS(Participantes[Seminario al que asistió],'Tablas Reporte'!B16) -> 4 | F16: Other | G16: =IF(Dashboard!$B$2=2025,COUNTIFS(Seminarios[Categoría],'Tablas Reporte'!F16,Seminarios[Año],2025),IF(Dashboard!$B$2=2024,COUNTIFS(Seminarios[Categoría],'Tablas Reporte'!F16,Seminarios[Año],2024),COUNTIFS(Seminarios[Categoría],'Tablas Reporte'!F16))) -> 1 | I16: Total | J16: =SUM(J14:J15) -> 52
B17: Visiting Scholars 11 | C17: Constantin Blome | D17: =COUNTIFS(Participantes[Seminario al que asistió],'Tablas Reporte'!B17) -> 16 | F17: Total | G17: =SUM(G12:G16) -> 45 | L17: Participants Types | M17: #
B18: Ágora | L18: Professor | M18: =IF(Dashboard!$B$2=2025,COUNTIFS(Participantes[Tipo Asistente],'Tablas Reporte'!L18,Participantes[Año],2025),IF(Dashboard!$B$2=2024,COUNTIFS(Participantes[Tipo Asistente],'Tablas Reporte'!L18,Participantes[Año],2024),COUNTIFS(Participantes[Tipo Asistente],'Tablas Reporte'!L18))) -> 610
B19: Ágora 1 | C19: Claudia Rebolledo | D19: =COUNTIFS(Participantes[Seminario al que asistió],'Tablas Reporte'!B19) -> 22 | F19: Seminar Area | G19: # | I19: Speakers Nationality | J19: # | L19: PhD student | M19: =IF(Dashboard!$B$2=2025,COUNTIFS(Participantes[Tipo Asistente],'Tablas Reporte'!L19,Participantes[Año],2025),IF(Dashboard!$B$2=2024,COUNTIFS(Participantes[Tipo Asistente],'Tablas Reporte'!L19,Participantes[Año],2024),COUNTIFS(Participantes[Tipo Asistente],'Tablas Reporte'!L19))) -> 87
B20: Ágora 2 | C20: John Thogersen | D20: =COUNTIFS(Participantes[Seminario al que asistió],'Tablas Reporte'!B20) -> 27 | F20: Sustainability | G20: =IF(Dashboard!$B$2=2025,COUNTIFS(Seminarios[Área],'Tablas Reporte'!F20,Seminarios[Año],2025),IF(Dashboard!$B$2=2024,COUNTIFS(Seminarios[Área],'Tablas Reporte'!F20,Seminarios[Año],2024),COUNTIFS(Seminarios[Área],'Tablas Reporte'!F20))) -> 5 | I20: Estados Unidos | J20: =IF(Dashboard!$B$2=2025,COUNTIFS(Conferencistas[Nacionalidad],I20,Conferencistas[Año],2025),IF(Dashboard!$B$2=2024,COUNTIFS(Conferencistas[Nacionalidad],I20,Conferencistas[Año],2024),COUNTIFS(Conferencistas[Nacionalidad],I20))) -> 8 | L20: Administrative | M20: =IF(Dashboard!$B$2=2025,COUNTIFS(Participantes[Tipo Asistente],'Tablas Reporte'!L20,Participantes[Año],2025),IF(Dashboard!$B$2=2024,COUNTIFS(Participantes[Tipo Asistente],'Tablas Reporte'!L20,Participantes[Año],2024),COUNTIFS(Participantes[Tipo Asistente],'Tablas Reporte'!L20))) -> 31
B21: Ágora 3 | C21: Marco Palacios | D21: =COUNTIFS(Participantes[Seminario al que asistió],'Tablas Reporte'!B21) -> 49 | F21: Marketing | G21: =IF(Dashboard!$B$2=2025,COUNTIFS(Seminarios[Área],'Tablas Reporte'!F21,Seminarios[Año],2025),IF(Dashboard!$B$2=2024,COUNTIFS(Seminarios[Área],'Tablas Reporte'!F21,Seminarios[Año],2024),COUNTIFS(Seminarios[Área],'Tablas Reporte'!F21))) -> 9 | I21: Alemania | J21: =IF(Dashboard!$B$2=2025,COUNTIFS(Conferencistas[Nacionalidad],I21,Conferencistas[Año],2025),IF(Dashboard!$B$2=2024,COUNTIFS(Conferencistas[Nacionalidad],I21,Conferencistas[Año],2024),COUNTIFS(Conferencistas[Nacionalidad],I21))) -> 6 | L21: External | M21: =IF(Dashboard!$B$2=2025,COUNTIFS(Participantes[Tipo Asistente],'Tablas Reporte'!L21,Participantes[Año],2025),IF(Dashboard!$B$2=2024,COUNTIFS(Participantes[Tipo Asistente],'Tablas Reporte'!L21,Participantes[Año],2024),COUNTIFS(Participantes[Tipo Asistente],'Tablas Reporte'!L21))) -> 213
B22: Ágora 4 | C22: Mirko Antino | D22: =COUNTIFS(Participantes[Seminario al que asistió],'Tablas Reporte'!B22) -> 26 | F22: Finance | G22: =IF(Dashboard!$B$2=2025,COUNTIFS(Seminarios[Área],'Tablas Reporte'!F22,Seminarios[Año],2025),IF(Dashboard!$B$2=2024,COUNTIFS(Seminarios[Área],'Tablas Reporte'!F22,Seminarios[Año],2024),COUNTIFS(Seminarios[Área],'Tablas Reporte'!F22))) -> 1 | I22: Colombia | J22: =IF(Dashboard!$B$2=2025,COUNTIFS(Conferencistas[Nacionalidad],I22,Conferencistas[Año],2025),IF(Dashboard!$B$2=2024,COUNTIFS(Conferencistas[Nacionalidad],I22,Conferencistas[Año],2024),COUNTIFS(Conferencistas[Nacionalidad],I22))) -> 20 | L22: Visiting professor | M22: =IF(Dashboard!$B$2=2025,COUNTIFS(Participantes[Tipo Asistente],'Tablas Reporte'!L22,Participantes[Año],2025),IF(Dashboard!$B$2=2024,COUNTIFS(Participantes[Tipo Asistente],'Tablas Reporte'!L22,Participantes[Año],2024),COUNTIFS(Participantes[Tipo Asistente],'Tablas Reporte'!L22))) -> 10
B23: Ágora 5 | C23: Felix Iturriaga | D23: =COUNTIFS(Participantes[Seminario al que asistió],'Tablas Reporte'!B23) -> 35 | F23: SCM & Technology | G23: =IF(Dashboard!$B$2=2025,COUNTIFS(Seminarios[Área],'Tablas Reporte'!F23,Seminarios[Año],2025),IF(Dashboard!$B$2=2024,COUNTIFS(Seminarios[Área],'Tablas Reporte'!F23,Seminarios[Año],2024),COUNTIFS(Seminarios[Área],'Tablas Reporte'!F23))) -> 4 | I23: Dinamarca | J23: =IF(Dashboard!$B$2=2025,COUNTIFS(Conferencistas[Nacionalidad],I23,Conferencistas[Año],2025),IF(Dashboard!$B$2=2024,COUNTIFS(Conferencistas[Nacionalidad],I23,Conferencistas[Año],2024),COUNTIFS(Conferencistas[Nacionalidad],I23))) -> 1 | L23: NA | M23: =IF(Dashboard!$B$2=2025,COUNTIFS(Participantes[Tipo Asistente],'Tablas Reporte'!L23,Participantes[Año],2025),IF(Dashboard!$B$2=2024,COUNTIFS(Participantes[Tipo Asistente],'Tablas Reporte'!L23,Participantes[Año],2024),COUNTIFS(Participantes[Tipo Asistente],'Tablas Reporte'!L23))+223) -> 268
B24: Ágora 6 | C24: Linda Alkire y Sertan Kabadayi | D24: =COUNTIFS(Participantes[Seminario al que asistió],'Tablas Reporte'!B24) -> 24 | F24: Management | G24: =IF(Dashboard!$B$2=2025,COUNTIFS(Seminarios[Área],'Tablas Reporte'!F24,Seminarios[Año],2025),IF(Dashboard!$B$2=2024,COUNTIFS(Seminarios[Área],'Tablas Reporte'!F24,Seminarios[Año],2024),COUNTIFS(Seminarios[Área],'Tablas Reporte'!F24))) -> 13 | I24: Eslovenia | J24: =IF(Dashboard!$B$2=2025,COUNTIFS(Conferencistas[Nacionalidad],I24,Conferencistas[Año],2025),IF(Dashboard!$B$2=2024,COUNTIFS(Conferencistas[Nacionalidad],I24,Conferencistas[Año],2024),COUNTIFS(Conferencistas[Nacionalidad],I24))) -> 1 | L24: Total | M24: =SUM(M18:M23) -> 1219
B25: Ágora 7 | C25: Andrew Parker | D25: =COUNTIFS(Participantes[Seminario al que asistió],'Tablas Reporte'!B25) -> 23 | F25: Strategy and Entrepreneurship | G25: =IF(Dashboard!$B$2=2025,COUNTIFS(Seminarios[Área],'Tablas Reporte'!F25,Seminarios[Año],2025),IF(Dashboard!$B$2=2024,COUNTIFS(Seminarios[Área],'Tablas Reporte'!F25,Seminarios[Año],2024),COUNTIFS(Seminarios[Área],'Tablas Reporte'!F25))) -> 4 | I25: Portugal | J25: =IF(Dashboard!$B$2=2025,COUNTIFS(Conferencistas[Nacionalidad],I25,Conferencistas[Año],2025),IF(Dashboard!$B$2=2024,COUNTIFS(Conferencistas[Nacionalidad],I25,Conferencistas[Año],2024),COUNTIFS(Conferencistas[Nacionalidad],I25))) -> 2
B26: Ágora 8 | C26: Wolf Wagner | D26: =COUNTIFS(Participantes[Seminario al que asistió],'Tablas Reporte'!B26) -> 17 | F26: Organizations | G26: =IF(Dashboard!$B$2=2025,COUNTIFS(Seminarios[Área],'Tablas Reporte'!F26,Seminarios[Año],2025),IF(Dashboard!$B$2=2024,COUNTIFS(Seminarios[Área],'Tablas Reporte'!F26,Seminarios[Año],2024),COUNTIFS(Seminarios[Área],'Tablas Reporte'!F26))) -> 9 | I26: UK | J26: =IF(Dashboard!$B$2=2025,COUNTIFS(Conferencistas[Nacionalidad],I26,Conferencistas[Año],2025),IF(Dashboard!$B$2=2024,COUNTIFS(Conferencistas[Nacionalidad],I26,Conferencistas[Año],2024),COUNTIFS(Conferencistas[Nacionalidad],I26))) -> 2
B27: Ágora 9 | C27: Neal Roese | D27: =COUNTIFS(Participantes[Seminario al que asistió],'Tablas Reporte'!B27) -> 25 | F27: Total | G27: =SUM(G20:G26) -> 45 | I27: Brazil | J27: =IF(Dashboard!$B$2=2025,COUNTIFS(Conferencistas[Nacionalidad],I27,Conferencistas[Año],2025),IF(Dashboard!$B$2=2024,COUNTIFS(Conferencistas[Nacionalidad],I27,Conferencistas[Año],2024),COUNTIFS(Conferencistas[Nacionalidad],I27))) -> 2
B28: GHE | I28: Italia | J28: =IF(Dashboard!$B$2=2025,COUNTIFS(Conferencistas[Nacionalidad],I28,Conferencistas[Año],2025),IF(Dashboard!$B$2=2024,COUNTIFS(Conferencistas[Nacionalidad],I28,Conferencistas[Año],2024),COUNTIFS(Conferencistas[Nacionalidad],I28))) -> 1
B29: GHE 1 | C29: Luis Fernando Molina | D29: =COUNTIFS(Participantes[Seminario al que asistió],'Tablas Reporte'!B29) -> 45 | I29: Egipto | J29: =IF(Dashboard!$B$2=2025,COUNTIFS(Conferencistas[Nacionalidad],I29,Conferencistas[Año],2025),IF(Dashboard!$B$2=2024,COUNTIFS(Conferencistas[Nacionalidad],I29,Conferencistas[Año],2024),COUNTIFS(Conferencistas[Nacionalidad],I29))) -> 1
B30: GHE 2 | C30: Orlando Grisales | D30: =COUNTIFS(Participantes[Seminario al que asistió],'Tablas Reporte'!B30) -> 56 | I30: España | J30: =IF(Dashboard!$B$2=2025,COUNTIFS(Conferencistas[Nacionalidad],I30,Conferencistas[Año],2025),IF(Dashboard!$B$2=2024,COUNTIFS(Conferencistas[Nacionalidad],I30,Conferencistas[Año],2024),COUNTIFS(Conferencistas[Nacionalidad],I30))) -> 4
B31: GHE 3 | C31: Alan Knight | D31: =COUNTIFS(Participantes[Seminario al que asistió],'Tablas Reporte'!B31)+223 -> 223 | I31: Argentina | J31: =IF(Dashboard!$B$2=2025,COUNTIFS(Conferencistas[Nacionalidad],I31,Conferencistas[Año],2025),IF(Dashboard!$B$2=2024,COUNTIFS(Conferencistas[Nacionalidad],I31,Conferencistas[Año],2024),COUNTIFS(Conferencistas[Nacionalidad],I31))) -> 1
B32: GHE 4 | C32: Eduardo Posada, Luis Gabriel Galán y más | D32: =COUNTIFS(Participantes[Seminario al que asistió],'Tablas Reporte'!B32) -> 55 | I32: Iran | J32: =IF(Dashboard!$B$2=2025,COUNTIFS(Conferencistas[Nacionalidad],I32,Conferencistas[Año],2025),IF(Dashboard!$B$2=2024,COUNTIFS(Conferencistas[Nacionalidad],I32,Conferencistas[Año],2024),COUNTIFS(Conferencistas[Nacionalidad],I32))) -> 1
B33: GHE 5 | C33: Manuel Rodriguez, Carlos Dávila, José Félix Lafaurie, Ximena Rueda y Lina Moros | D33: =COUNTIFS(Participantes[Seminario al que asistió],'Tablas Reporte'!B33) -> 55 | I33: Irlanda | J33: =IF(Dashboard!$B$2=2025,COUNTIFS(Conferencistas[Nacionalidad],I33,Conferencistas[Año],2025),IF(Dashboard!$B$2=2024,COUNTIFS(Conferencistas[Nacionalidad],I33,Conferencistas[Año],2024),COUNTIFS(Conferencistas[Nacionalidad],I33))) -> 1
B34: Recruitment research seminars | I34: China | J34: =IF(Dashboard!$B$2=2025,COUNTIFS(Conferencistas[Nacionalidad],I34,Conferencistas[Año],2025),IF(Dashboard!$B$2=2024,COUNTIFS(Conferencistas[Nacionalidad],I34,Conferencistas[Año],2024),COUNTIFS(Conferencistas[Nacionalidad],I34))) -> 1
B35: Recruitment research 1 | C35: Juliana Moreira Batista | D35: =COUNTIFS(Participantes[Seminario al que asistió],'Tablas Reporte'!B35) -> 13 | I35: Total | J35: =SUM(J20:J34) -> 52
B36: Recruitment research 2 | C36: Camilo Rojas | D36: =COUNTIFS(Participantes[Seminario al que asistió],'Tablas Reporte'!B36) -> 12
B37: Recruitment research 3 | C37: Basel Hammoda | D37: =COUNTIFS(Participantes[Seminario al que asistió],'Tablas Reporte'!B37) -> 11
B38: Recruitment research 4 | C38: Eduardo Boada | D38: =COUNTIFS(Participantes[Seminario al que asistió],'Tablas Reporte'!B38) -> 11
B39: Recruitment research 5 | C39: Nicolás Parra | D39: =COUNTIFS(Participantes[Seminario al que asistió],'Tablas Reporte'!B39) -> 11
B40: Recruitment research 6 | C40: Sasmira Matta | D40: =COUNTIFS(Participantes[Seminario al que asistió],'Tablas Reporte'!B40) -> 11
B41: Recruitment research 7 | C41: Lina Lozano | D41: =COUNTIFS(Participantes[Seminario al que asistió],'Tablas Reporte'!B41) -> 15
B42: Recruitment research 8 | C42: Andres Espitia | D42: =COUNTIFS(Participantes[Seminario al que asistió],'Tablas Reporte'!B42) -> 16
...

Sheet Listas Asistencia
B2: Seminario: | C2: Visiting Scholars 13
B4: Nombre del Seminario: | C4: =_xlfn.XLOOKUP($C$2,Seminarios[Seminario],Seminarios[Nombre del seminario],"NA") -> Climate Change and Business: Historical Perspectives on the Andes Wine Industry and the Rise of Greenwashing
B5: Conferencista 1: | C5: =_xlfn.XLOOKUP($C$2,Seminarios[Seminario],Seminarios[Conferencista 1],"NA") -> Teresa da Silva Lopes
B6: Conferencista 2: | C6: =_xlfn.XLOOKUP($C$2,Seminarios[Seminario],Seminarios[Conferencista 2],"NA") -> NA
B7: Conferencista 3: | C7: =_xlfn.XLOOKUP($C$2,Seminarios[Seminario],Seminarios[Conferencista 3],"NA") -> NA
B8: Conferencista 4: | C8: =_xlfn.XLOOKUP($C$2,Seminarios[Seminario],Seminarios[Conferencista 4],"NA") -> NA
B9: Conferencista 5: | C9: =_xlfn.XLOOKUP($C$2,Seminarios[Seminario],Seminarios[Conferencista 5],"NA") -> NA
B10: Fecha: | C10: =_xlfn.XLOOKUP($C$2,Seminarios[Seminario],Seminarios[Fecha],"NA") -> 45845
B11: Hora: | C11: =_xlfn.XLOOKUP($C$2,Seminarios[Seminario],Seminarios[Hora],"NA") -> 12:30pm
B12: Lugar: | C12: =_xlfn.XLOOKUP($C$2,Seminarios[Seminario],Seminarios[Lugar],"NA") -> SD 702
B13: # Asistentes: | C13: =COUNTA(B18:B1048576) -> 21
B16: Lista Participantes
B17: Nombre | C17: Correo | D17: Género | E17: Tipo Asistente | F17: Modalidad | G17: Seminario al que asistió
B18: {=IFERROR(_xlfn._xlws.FILTER(Participantes[Nombre],Participantes[Seminario al que asistió]='Listas Asistencia'!$C$2),"")} -> Norma Ortiz | C18: {=IFERROR(_xlfn._xlws.FILTER(Participantes[Correo],Participantes[Seminario al que asistió]='Listas Asistencia'!$C$2),"")} -> nc.ortiz@uniandes.edu.co | D18: {=IFERROR(_xlfn._xlws.FILTER(Participantes[Género],Participantes[Seminario al que asistió]='Listas Asistencia'!$C$2),"")} -> F | E18: {=IFERROR(_xlfn._xlws.FILTER(Participantes[Tipo Asistente],Participantes[Seminario al que asistió]='Listas Asistencia'!$C$2),"")} -> Professor | F18: {=IFERROR(_xlfn._xlws.FILTER(Participantes[Modalidad],Participantes[Seminario al que asistió]='Listas Asistencia'!$C$2),"")} -> On-Campus | G18: {=IFERROR(_xlfn._xlws.FILTER(Participantes[Seminario al que asistió],Participantes[Seminario al que asistió]='Listas Asistencia'!$C$2),"")} -> Visiting Scholars 13
B19: Maximiliano Gonzalez | C19: maxgonza@uniandes.edu.co | D19: M | E19: Professor | F19: On-Campus | G19: Visiting Scholars 13
B20: Julia Rosa Romero | C20: jr.romero109@uniandes.edu.co | D20: F | E20: Professor | F20: On-Campus | G20: Visiting Scholars 13
B21: Juan Esteban Nieto Campos | C21: je.nieto@uniandes.edu.co | D21: M | E21: Administrative | F21: On-Campus | G21: Visiting Scholars 13
B22: Nathalia Franco | C22: nath-fra@uniandes.edu.co | D22: F | E22: Professor | F22: On-Campus | G22: Visiting Scholars 13
B23: Carolina Dávila | C23: cadavila@uniandes.edu.co | D23: F | E23: Administrative | F23: On-Campus | G23: Visiting Scholars 13
B24: Juan Camilo Ángel Aguirre | C24: jc.angela1@uniandes.edu.co | D24: M | E24: Administrative | F24: On-Campus | G24: Visiting Scholars 13
B25: Carlos Dávila | C25: cdavila@uniandes.edu.co | D25: M | E25: Professor | F25: On-Campus | G25: Visiting Scholars 13
B26: Jose David Martinez | C26: jd.martinezo@uniandes.edu.co | D26: M | E26: Administrative | F26: On-Campus | G26: Visiting Scholars 13
B27: Lina Moros | C27: limoros@gmail.com | D27: F | E27: Professor | F27: On-Campus | G27: Visiting Scholars 13
B28: Carlos Trujillo | C28: ctrujill@uniandes.edu.co | D28: M | E28: Professor | F28: On-Campus | G28: Visiting Scholars 13
B29: Mumbi Wachira | C29: mwachira@strathmore.edu | D29: F | E29: Visiting professor | F29: On-Campus | G29: Visiting Scholars 13
B30: Fiorenza Zlatar | C30: f.zlatar@uniandes.edu.co | D30: F | E30: PhD Student | F30: On-Campus | G30: Visiting Scholars 13
... B36: Manuel Rodriguez | C36: mrb@uniandes.edu.co | D36: M | E36: Professor | F36: On-Campus | G36: Visiting Scholars 13
B37: Juliana Angulo | C37: 0 | D37: F | E37: PhD Student | F37: On-Campus | G37: Visiting Scholars 13
B38: German Andrade | C38: gandrade@uniandes.edu.co | D38: M | E38: Professor | F38: On-Campus | G38: Visiting Scholars 13

Sheet BD Seminarios
A1: Seminario | B1: Categoría | C1: Nombre del seminario | D1: Conferencista 1 | E1: Conferencista 2 | F1: Conferencista 3 | G1: Conferencista 4 | H1: Conferencista 5 | I1: Fecha | J1: Hora | K1: Año | L1: Modalidad | M1: Lugar | N1: Área
A2: Visiting Scholars 1 | B2: Visiting Scholars Seminar Series | C2: Two Wrongs Don’t Make a Right, or Do They? Third Parties’ Ethical Leadership Perceptions Depend on Preceding Follower Behavior | D2: Niels Van Quaquebeke | E2: NA | F2: NA | G2: NA | H2: NA | I2: 45370 | J2: 0.375 | K2: =YEAR(Seminarios[[#This Row],[Fecha]]) -> 2024 | L2: On-Campus | M2: SD 704 | N2: Organizations | P2: =IF(Dashboard!$B$2=2025,COUNTIF(Seminarios[Año],2025),IF(Dashboard!$B$2=2024,COUNTIF(Seminarios[Año],2024),COUNTA(Seminarios[Seminario]))) -> 45
A3: Visiting Scholars 2 | B3: Visiting Scholars Seminar Series | C3: Exploring the impact of diverse perspectives in Echo Chambers: An empirical evaluation of the random Dynamical Nudge Model | D3: Bryan Charles Boots | E3: NA | F3: NA | G3: NA | H3: NA | I3: 45407 | J3: 0.52083333 | K3: =YEAR(Seminarios[[#This Row],[Fecha]]) -> 2024 | L3: On-Campus | M3: SD 805 | N3: SCM & Technology
A4: Visiting Scholars 3 | B4: Visiting Scholars Seminar Series | C4: Specialty Coffee: Emergent Themes on Inequity in the Value System | D4: Spencer Ross | E4: NA | F4: NA | G4: NA | H4: NA | I4: 45411 | J4: 0.52083333 | K4: =YEAR(Seminarios[[#This Row],[Fecha]]) -> 2024 | L4: On-Campus | M4: SD 701 | N4: Marketing
A5: Visiting Scholars 4 | B5: Visiting Scholars Seminar Series | C5: Do women overprepare? An experimental analysis | D5: Christiane Schwieren | E5: NA | F5: NA | G5: NA | H5: NA | I5: 45460 | J5: 0.45833333 | K5: =YEAR(Seminarios[[#This Row],[Fecha]]) -> 2024 | L5: Online | M5: Virtual | N5: Sustainability
A6: Visiting Scholars 5 | B6: Visiting Scholars Seminar Series | C6: How can sustainable marketers build their brands? A closer look into greenwashing and CSR reputation | D6: Barbara Culiberg | E6: NA | F6: NA | G6: NA | H6: NA | I6: 45460 | J6: 0.45833333 | K6: =YEAR(Seminarios[[#This Row],[Fecha]]) -> 2024 | L6: Hybrid | M6: Hibrido | N6: Marketing
A7: Visiting Scholars 6 | B7: Visiting Scholars Seminar Series | C7: Coffee, the EU Deforestation Regulation and social enterprise resilience: insights into ongoing research | D7: Janina Grabs | E7: Rita Motta | F7: NA | G7: NA | H7: NA | I7: 45364 | J7: 0.5 | K7: =YEAR(Seminarios[[#This Row],[Fecha]]) -> 2024 | L7: On-Campus | M7: SD 704 | N7: Sustainability
A8: Ágora 1 | B8: Ágora | C8: Exploring Indigenous Procurement in Canada | D8: Claudia Rebolledo | E8: NA | F8: NA | G8: NA | H8: NA | I8: 45386 | J8: 0.54166667 | K8: =YEAR(Seminarios[[#This Row],[Fecha]]) -> 2024 | L8: Online | M8: Virtual | N8: SCM & Technology
A9: Ágora 2 | B9: Ágora | C9: The role of norm dynamics in the formation of sustainable behaviours | D9: John Thøgersen | E9: NA | F9: NA | G9: NA | H9: NA | I9: 45428 | J9: NA | K9: =YEAR(Seminarios[[#This Row],[Fecha]]) -> 2024 | L9: On-Campus | M9: SD 801 | N9: Sustainability
A10: GHE 1 | B10: GHE | C10: Libro Leo S. Kopp 1858-1927. Historia de un visionario | D10: Luis Fernando Molina | E10: NA | F10: NA | G10: NA | H10: NA | I10: 45335 | J10: NA | K10: =YEAR(Seminarios[[#This Row],[Fecha]]) -> 2024 | L10: Hybrid | M10: Hibrido | N10: Management
A11: GHE 2 | B11: GHE | C11: Bavaria 1889-1950. Del paternalismo a la tecnocracia | D11: Orlando Grisales | E11: NA | F11: NA | G11: NA | H11: NA | I11: 45398 | J11: NA | K11: =YEAR(Seminarios[[#This Row],[Fecha]]) -> 2024 | L11: Hybrid | M11: Hibrido | N11: Management
A12: GHE 3 | B12: GHE | D12: Alan Knight | E12: NA | F12: NA | G12: NA | H12: NA | I12: NA | J12: NA | K12: 2024 | L12: Hybrid | M12: NA | N12: Management
A13: Oligarchs - David L. | B13: Other | C13: Oligarchs and Entrepreneurship | D13: David Lingelbach | E13: NA | F13: NA | G13: NA | H13: NA | I13: 45500 | J13: 0.52083333 | K13: =YEAR(Seminarios[[#This Row],[Fecha]]) -> 2024 | L13: Hybrid | M13: Hibrido | N13: Strategy and Entrepreneurship
A14: Ágora 3 | B14: Ágora | C14: El rol de los empresarios en el desarrollo de Bogotá y su ocupación | D14: Marco Palacios | E14: NA | F14: NA | G14: NA | H14: NA | I14: 45512 | J14: 0.52083333 | K14: =YEAR(Seminarios[[#This Row],[Fecha]]) -> 2024 | L14: Hybrid | M14: Hibrido | N14: Organizations
A15: Recruitment research 1 | B15: Recruitment research seminars | C15: Sarcastic or Assertive: How Should Brands Reply to Consumers’ Uncivil Comments on Social Media in the Context of Brand Activism? | D15: Juliana Moreira Batista | E15: NA | F15: NA | G15: NA | H15: NA | I15: 45527 | J15: 0.45833333 | K15: =YEAR(Seminarios[[#This Row],[Fecha]]) -> 2024 | L15: Online | M15: Virtual | N15: Marketing
A16: GHE 4 | B16: GHE | C16: Los Empresarios y sus Comunicaciones en Colombia: Una Perspectiva Histórica | D16: Eduardo Posada Carbó | E16: Luis Gabriel Galán | F16: James V. Torres Moreno | G16: Carlos Dávila | H16: NA | I16: 45531 | J16: 0.52083333 | K16: =YEAR(Seminarios[[#This Row],[Fecha]]) -> 2024 | L16: Hybrid | M16: SD 809 y Zoom | N16: Management
A17: Recruitment research 2 | B17: Recruitment research seminars | C17: Engaging Emotion and Reason: Multidimensional and Multigroup Analysis of Value Co-Creation Behavior in E-commerce | D17: Camilo Rojas | E17: NA | F17: NA | G17: NA | H17: NA | I17: 45531 | J17: 0.4375 | K17: =YEAR(Seminarios[[#This Row],[Fecha]]) -> 2024 | L17: On-Campus | M17: SD 1003 | N17: Marketing
A18: Ágora 4 | B18: Ágora | C18: Capturing dynamic organizational phenomena: methodological challenges and opportunities | D18: Mirko Antino | E18: NA | F18: NA | G18: NA | H18: NA | I18: 45554 | J18: 0.52083333 | K18: =YEAR(Seminarios[[#This Row],[Fecha]]) -> 2024 | L18: On-Campus | M18: SD 701 | N18: Organizations
A19: Recruitment research 3 | B19: Recruitment research seminars | C19: Extracurricular activities for entrepreneurial learning: A typology based on learning theories | D19: Basel Hammoda | E19: NA | F19: NA | G19: NA | H19: NA | I19: 45560 | J19: 0.41666667 | K19: =YEAR(Seminarios[[#This Row],[Fecha]]) -> 2024 | L19: Online | M19: Virtual | N19: Strategy and Entrepreneurship
A20: GHE 5 | B20: GHE | C20: Conversatorio - Presente y Futuro del Medio Ambiente en Colombia | D20: Manuel Rodriguez Becerra | E20: Carlos Dávila | F20: José Félix Lafaurie | G20: Ximena Rueda | H20: Lina Moros | I20: 45559 | J20: 0.52083333 | K20: =YEAR(Seminarios[[#This Row],[Fecha]]) -> 2024 | L20: Hybrid | M20: SD y Zoom | N20: Management
A21: Recruitment research 4 | B21: Recruitment research seminars | C21: Damned if you do, damned if you don’t: How counterfactual emotions shape early-stage investment decision-making | D21: Eduardo Boada | E21: NA | F21: NA | G21: NA | H21: NA | I21: 45561 | J21: 0.58333333 | K21: =YEAR(Seminarios[[#This Row],[Fecha]]) -> 2024 | L21: Online | M21: Virtual | N21: Strategy and Entrepreneurship
A22: Ágora 5 | B22: Ágora | C22: La investigación internacional en gobierno corporativo: Una revisión | D22: Felix Iturriaga | E22: NA | F22: NA | G22: NA | H22: NA | I22: 45582 | J22: 0.52083333 | K22: =YEAR(Seminarios[[#This Row],[Fecha]]) -> 2024 | L22: On-Campus | M22: W102 | N22: Organizations
A23: Recruitment research 5 | B23: Recruitment research seminars | C23: A road not taken in alternative dispute resolution | D23: Nicolás Parra | E23: NA | F23: NA | G23: NA | H23: NA | I23: 45586 | J23: 0.52083333 | K23: =YEAR(Seminarios[[#This Row],[Fecha]]) -> 2024 | L23: Online | M23: Virtual | N23: Organizations
A24: Ágora 6 | B24: Ágora | C24: Transformative Service Research: Interdiciplinary Research for Advanced Well-being and Social Impact | D24: Linda Alkire | E24: Sertan Kabadayi | F24: NA | G24: NA | H24: NA | I24: 45609 | J24: 0.52083333 | K24: =YEAR(Seminarios[[#This Row],[Fecha]]) -> 2024 | L24: On-Campus | M24: SD 801 | N24: Marketing
... A43: Visiting Scholars 11 | B43: Visiting Scholars Seminar Series | C43: The Role of Digital Transformation in Enhancing Social Sustainability in Supply Chains | D43: Constantin Blome | E43: NA | F43: NA | G43: NA | H43: NA | I43: 45799 | J43: 0.52083333 | K43: =YEAR(Seminarios[[#This Row],[Fecha]]) -> 2025 | L43: On-Campus | M43: SD 807 | N43: SCM & Technology
A44: Visiting Scholars 12 | B44: Visiting Scholars Seminar Series | C44: Advancing Education for Sustainability & Global Citizenship in business schools | D44: Christian Schott | E44: NA | F44: NA | G44: NA | H44: NA | I44: 45817 | J44: 12:30pm | K44: =YEAR(Seminarios[[#This Row],[Fecha]]) -> 2025 | L44: On-Campus | M44: SD 809 | N44: Sustainability
A45: Visiting Scholars 13 | B45: Visiting Scholars Seminar Series | C45: Climate Change and Business: Historical Perspectives on the Andes Wine Industry and the Rise of Greenwashing | D45: Teresa da Silva Lopes | E45: NA | F45: NA | G45: NA | H45: NA | I45: 45845 | J45: 12:30pm | K45: =YEAR(Seminarios[[#This Row],[Fecha]]) -> 2025 | L45: On-Campus | M45: SD 702 | N45: Sustainability
A46: GHE 6 | B46: GHE | C46: International Business, Strategy and Entrepreneurship: How History Matters | D46: Teresa da Silva Lopes | E46: NA | F46: NA | G46: NA | H46: NA | I46: 45848 | J46: 12:30pm | K46: =YEAR(Seminarios[[#This Row],[Fecha]]) -> 2025 | L46: Hybrid | M46: SD 809 | N46: Management

Sheet BD Participantes
A1: Nombre | B1: Correo | C1: Género | D1: Tipo Asistente | E1: Modalidad | F1: Seminario al que asistió | G1: Año
A2: Roberto Gutiérrez | B2: robgutie | C2: M | D2: Professor | E2: On-Campus | F2: Visiting Scholars 1 | G2: =_xlfn.XLOOKUP(Participantes[[#This Row],[Seminario al que asistió]],Seminarios[Seminario],Seminarios[Año]) -> 2024 | I2: =IF(Dashboard!$B$2=2025,COUNTIF(Participantes[Año],2025),IF(Dashboard!$B$2=2024,COUNTIF(Participantes[Año],2024),COUNTA(Participantes[Seminario al que asistió]))+223) -> 1219
A3: Pilar Sánchez | B3: p.sanchez1@uniandes.edu.co | C3: F | D3: Professor | E3: On-Campus | F3: Visiting Scholars 1 | G3: =_xlfn.XLOOKUP(Participantes[[#This Row],[Seminario al que asistió]],Seminarios[Seminario],Seminarios[Año]) -> 2024
A4: Ximena Rueda | B4: x.rueda@uniandes.edu.co | C4: F | D4: Professor | E4: On-Campus | F4: Visiting Scholars 1 | G4: =_xlfn.XLOOKUP(Participantes[[#This Row],[Seminario al que asistió]],Seminarios[Seminario],Seminarios[Año]) -> 2024
A5: María Consuelo Cárdenas | B5: marcarde@uniandes.edu.co | C5: F | D5: Professor | E5: On-Campus | F5: Visiting Scholars 1 | G5: =_xlfn.XLOOKUP(Participantes[[#This Row],[Seminario al que asistió]],Seminarios[Seminario],Seminarios[Año]) -> 2024
A6: Simon Turner | B6: s.turner@uniandes.edu.co | C6: M | D6: Professor | E6: On-Campus | F6: Visiting Scholars 1 | G6: =_xlfn.XLOOKUP(Participantes[[#This Row],[Seminario al que asistió]],Seminarios[Seminario],Seminarios[Año]) -> 2024
A7: Sebastian Schorch | B7: sl.schorch@uniandes.edu.co | C7: M | D7: Professor | E7: On-Campus | F7: Visiting Scholars 1 | G7: =_xlfn.XLOOKUP(Participantes[[#This Row],[Seminario al que asistió]],Seminarios[Seminario],Seminarios[Año]) -> 2024
A8: Iván Darío Sánchez Manchola | B8: id.sanchez41@uniandes.edu.co | C8: M | D8: Professor | E8: On-Campus | F8: Visiting Scholars 1 | G8: =_xlfn.XLOOKUP(Participantes[[#This Row],[Seminario al que asistió]],Seminarios[Seminario],Seminarios[Año]) -> 2024
A9: Nathalie Mendez Mendez | B9: n.mendez52@uniandes.edu.co | C9: F | D9: PhD Student | E9: On-Campus | F9: Visiting Scholars 1 | G9: =_xlfn.XLOOKUP(Participantes[[#This Row],[Seminario al que asistió]],Seminarios[Seminario],Seminarios[Año]) -> 2024
A10: Minoru Higa | B10: d.higa@uniandes.edu.co | C10: M | D10: Professor | E10: On-Campus | F10: Visiting Scholars 1 | G10: =_xlfn.XLOOKUP(Participantes[[#This Row],[Seminario al que asistió]],Seminarios[Seminario],Seminarios[Año]) -> 2024
A11: Marco Antonio Azuero Isaza | B11: mazuero@uniandes.edu.co | C11: M | D11: Professor | E11: On-Campus | F11: Visiting Scholars 1 | G11: =_xlfn.XLOOKUP(Participantes[[#This Row],[Seminario al que asistió]],Seminarios[Seminario],Seminarios[Año]) -> 2024
A12: Tatiana Rodriguez | B12: t.rodriguez79@uniandes.edu.co | C12: F | D12: Professor | E12: On-Campus | F12: Visiting Scholars 1 | G12: =_xlfn.XLOOKUP(Participantes[[#This Row],[Seminario al que asistió]],Seminarios[Seminario],Seminarios[Año]) -> 2024
A13: Margarita Canal | B13: mca-l@uniandes.edu.co | C13: F | D13: Professor | E13: On-Campus | F13: Visiting Scholars 1 | G13: =_xlfn.XLOOKUP(Participantes[[#This Row],[Seminario al que asistió]],Seminarios[Seminario],Seminarios[Año]) -> 2024
A14: Emilio Cardona | B14: e-cardon@uniandes.edu.co | C14: M | D14: Professor | E14: On-Campus | F14: Visiting Scholars 1 | G14: =_xlfn.XLOOKUP(Participantes[[#This Row],[Seminario al que asistió]],Seminarios[Seminario],Seminarios[Año]) -> 2024
... A333: Ingrid Bolivar | B333: ibolivar@uniandes.edu.co | C333: F | D333: Professor | E333: On-Campus | F333: GHE 4 | G333: =_xlfn.XLOOKUP(Participantes[[#This Row],[Seminario al que asistió]],Seminarios[Seminario],Seminarios[Año]) -> 2024
A334: Ramiro | C334: M | D334: External | E334: On-Campus | F334: GHE 4 | G334: =_xlfn.XLOOKUP(Participantes[[#This Row],[Seminario al que asistió]],Seminarios[Seminario],Seminarios[Año]) -> 2024
A335: José Alberto Pérez Toro | B335: joseaperez20216@gmail.com | C335: M | D335: External | E335: On-Campus | F335: GHE 4 | G335: =_xlfn.XLOOKUP(Participantes[[#This Row],[Seminario al que asistió]],Seminarios[Seminario],Seminarios[Año]) -> 2024
A336: Eduardo Posada Carbó | C336: M | D336: External | E336: Online | F336: GHE 4 | G336: =_xlfn.XLOOKUP(Participantes[[#This Row],[Seminario al que asistió]],Seminarios[Seminario],Seminarios[Año]) -> 2024
A337: Fernando Ospina | C337: M | D337: External | E337: Online | F337: GHE 4 | G337: =_xlfn.XLOOKUP(Participantes[[#This Row],[Seminario al que asistió]],Seminarios[Seminario],Seminarios[Año]) -> 2024
A338: Jaime Ruíz | B338: jruiz@uniandes.edu.co | C338: M | D338: Professor | E338: Online | F338: GHE 4 | G338: =_xlfn.XLOOKUP(Participantes[[#This Row],[Seminario al que asistió]],Seminarios[Seminario],Seminarios[Año]) -> 2024
A339: Felipe Klopstock Triana | B339: f.klopstock@uniandes.edu.co | C339: M | D339: Professor | E339: Online | F339: GHE 4 | G339: =_xlfn.XLOOKUP(Participantes[[#This Row],[Seminario al que asistió]],Seminarios[Seminario],Seminarios[Año]) -> 2024
A340: Daniela Lopez Palacio | B340: dalopezpa@unal.edu.co | C340: F | D340: External | E340: Online | F340: GHE 4 | G340: =_xlfn.XLOOKUP(Participantes[[#This Row],[Seminario al que asistió]],Seminarios[Seminario],Seminarios[Año]) -> 2024
A341: Amparo Jimenez | B341: jimenez.amparo@uqam.ca | C341: F | D341: External | E341: Online | F341: GHE 4 | G341: =_xlfn.XLOOKUP(Participantes[[#This Row],[Seminario al que asistió]],Seminarios[Seminario],Seminarios[Año]) -> 2024
A342: Jorge Varela-Yepes | B342: jorge.yepes.14@ucl.ac.uk | C342: M | D342: External | E342: Online | F342: GHE 4 | G342: =_xlfn.XLOOKUP(Participantes[[#This Row],[Seminario al que asistió]],Seminarios[Seminario],Seminarios[Año]) -> 2024
A343: José Alberto Bedoya Ramos | B343: jbedoya@fundacionsantodomingo.org | C343: M | D343: External | E343: Online | F343: GHE 4 | G343: =_xlfn.XLOOKUP(Participantes[[#This Row],[Seminario al que asistió]],Seminarios[Seminario],Seminarios[Año]) -> 2024
A344: Sonia M. Jaimes | B344: sonmil@gmail.com | C344: F | D344: External | E344: Online | F344: GHE 4 | G344: =_xlfn.XLOOKUP(Participantes[[#This Row],[Seminario al que asistió]],Seminarios[Seminario],Seminarios[Año]) -> 2024
A345: Ana Sofia Beltran Guerrero | B345: As.beltrang1@uniandes.edu.co | C345: F | D345: Professor | E345: Online | F345: GHE 4 | G345: =_xlfn.XLOOKUP(Participantes[[#This Row],[Seminario al que asistió]],Seminarios[Seminario],Seminarios[Año]) -> 2024
A346: Juan Ignacio Neves-Sarriegui | B346: juan.nevessarriegui@history.ox.ac.uk | C346: M | D346: External | E346: Online | F346: GHE 4 | G346: =_xlfn.XLOOKUP(Participantes[[#This Row],[Seminario al que asistió]],Seminarios[Seminario],Seminarios[Año]) -> 2024
A347: Mateo Ramos | C347: M | D347: External | E347: Online | F347: GHE 4 | G347: =_xlfn.XLOOKUP(Participantes[[#This Row],[Seminario al que asistió]],Seminarios[Seminario],Seminarios[Año]) -> 2024
A348: Paola Ruiz | B348: ruiz.paola@gmail.com | C348: F | D348: External | E348: Online | F348: GHE 4 | G348: =_xlfn.XLOOKUP(Participantes[[#This Row],[Seminario al que asistió]],Seminarios[Seminario],Seminarios[Año]) -> 2024
A349: Isa Martínez | C349: F | D349: External | E349: Online | F349: GHE 4 | G349: =_xlfn.XLOOKUP(Participantes[[#This Row],[Seminario al que asistió]],Seminarios[Seminario],Seminarios[Año]) -> 2024
A350: Minoru Higa | B350: d.higa@uniandes.edu.co | C350: M | D350: Professor | E350: Online | F350: GHE 4 | G350: =_xlfn.XLOOKUP(Participantes[[#This Row],[Seminario al que asistió]],Seminarios[Seminario],Seminarios[Año]) -> 2024
A351: Amanda Gabriela Contreras Cárdenas | B351: ag.contreras@uniandes.edu.co | C351: F | D351: PhD Student | E351: Online | F351: GHE 4 | G351: =_xlfn.XLOOKUP(Participantes[[#This Row],[Seminario al que asistió]],Seminarios[Seminario],Seminarios[Año]) -> 2024
A352: Lucia Buitrago Echeverri | B352: l.buitragoe@uniandes.edu.co | C352: F | D352: PhD Student | E352: Online | F352: GHE 4 | G352: =_xlfn.XLOOKUP(Participantes[[#This Row],[Seminario al que asistió]],Seminarios[Seminario],Seminarios[Año]) -> 2024
A353: Alejandra Watanable Farro | B353: alwatana@ucsc.edu | C353: F | D353: External | E353: Online | F353: GHE 4 | G353: =_xlfn.XLOOKUP(Participantes[[#This Row],[Seminario al que asistió]],Seminarios[Seminario],Seminarios[Año]) -> 2024
A354: Edisantiago Gutierrez Gil | B354: e.gutierrez12@uniandes.edu.co | C354: M | D354: Administrative | E354: Online | F354: GHE 4 | G354: =_xlfn.XLOOKUP(Participantes[[#This Row],[Seminario al que asistió]],Seminarios[Seminario],Seminarios[Año]) -> 2024
A355: Gustavo Bell Lemus | B355: acuariusbell57@hotmail.com | C355: M | D355: External | E355: Online | F355: GHE 4 | G355: =_xlfn.XLOOKUP(Participantes[[#This Row],[Seminario al que asistió]],Seminarios[Seminario],Seminarios[Año]) -> 2024
A356: Mariana Naranjo | C356: F | D356: External | E356: Online | F356: GHE 4 | G356: =_xlfn.XLOOKUP(Participantes[[#This Row],[Seminario al que asistió]],Seminarios[Seminario],Seminarios[Año]) -> 2024
A357: Catalina Gomez Peña | C357: F | D357: External | E357: Online | F357: GHE 4 | G357: =_xlfn.XLOOKUP(Participantes[[#This Row],[Seminario al que asistió]],Seminarios[Seminario],Seminarios[Año]) -> 2024
A358: Martha H. Saravia | C358: F | D358: External | E358: Online | F358: GHE 4 | G358: =_xlfn.XLOOKUP(Participantes[[#This Row],[Seminario al que asistió]],Seminarios[Seminario],Seminarios[Año]) -> 2024
...

Sheet BD Conferencistas
A1: Nombre | B1: Apellido | C1: Nombre Completo | D1: Genero | E1: Nacionalidad | F1: Fecha nacimiento | G1: Nombre Universidad origen | H1: País Universidad origen | I1: Ubicación | J1: Seminario que dirigió | K1: Año
A2: Bryan Charles | B2: Boots | C2: =_xlfn.CONCAT(Conferencistas[[#This Row],[Nombre]]," ",Conferencistas[[#This Row],[Apellido]]) -> Bryan Charles Boots | D2: Male | E2: Estados Unidos | F2: 31942 | G2: University of Missouri | H2: Estados Unidos | I2: North America | J2: =_xlfn.XLOOKUP(Conferencistas[[#This Row],[Nombre Completo]],Seminarios[Conferencista 1],Seminarios[Seminario],_xlfn.XLOOKUP(Conferencistas[[#This Row],[Nombre Completo]],Seminarios[Conferencista 2],Seminarios[Seminario],_xlfn.XLOOKUP(Conferencistas[[#This Row],[Nombre Completo]],Seminarios[Conferencista 3],Seminarios[Seminario],_xlfn.XLOOKUP(Conferencistas[[#This Row],[Nombre Completo]],Seminarios[Conferencista 4],Seminarios[Seminario],_xlfn.XLOOKUP(Conferencistas[[#This Row],[Nombre Completo]],Seminarios[Conferencista 5],Seminarios[Seminario]))))) -> Visiting Scholars 2 | K2: =_xlfn.XLOOKUP(Conferencistas[[#This Row],[Seminario que dirigió]],Seminarios[Seminario],Seminarios[Año]) -> 2024 | M2: =IF(Dashboard!$B$2=2025,COUNTIF(Conferencistas[Año],2025),IF(Dashboard!$B$2=2024,COUNTIF(Conferencistas[Año],2024),COUNTA(Conferencistas[Nombre Completo]))) -> 52
A3: Christiane | B3: Schwieren | C3: =_xlfn.CONCAT(Conferencistas[[#This Row],[Nombre]]," ",Conferencistas[[#This Row],[Apellido]]) -> Christiane Schwieren | D3: Female | E3: Alemania | F3: 26326 | G3: University of Heidelberg | H3: Alemania | I3: Europe | J3: =_xlfn.XLOOKUP(Conferencistas[[#This Row],[Nombre Completo]],Seminarios[Conferencista 1],Seminarios[Seminario],_xlfn.XLOOKUP(Conferencistas[[#This Row],[Nombre Completo]],Seminarios[Conferencista 2],Seminarios[Seminario],_xlfn.XLOOKUP(Conferencistas[[#This Row],[Nombre Completo]],Seminarios[Conferencista 3],Seminarios[Seminario],_xlfn.XLOOKUP(Conferencistas[[#This Row],[Nombre Completo]],Seminarios[Conferencista 4],Seminarios[Seminario],_xlfn.XLOOKUP(Conferencistas[[#This Row],[Nombre Completo]],Seminarios[Conferencista 5],Seminarios[Seminario]))))) -> Visiting Scholars 4 | K3: =_xlfn.XLOOKUP(Conferencistas[[#This Row],[Seminario que dirigió]],Seminarios[Seminario],Seminarios[Año]) -> 2024
A4: Spencer | B4: Ross | C4: =_xlfn.CONCAT(Conferencistas[[#This Row],[Nombre]]," ",Conferencistas[[#This Row],[Apellido]]) -> Spencer Ross | D4: Male | E4: Estados Unidos | F4: 30184 | G4: University of Massachusetts | H4: Estados Unidos | I4: North America | J4: =_xlfn.XLOOKUP(Conferencistas[[#This Row],[Nombre Completo]],Seminarios[Conferencista 1],Seminarios[Seminario],_xlfn.XLOOKUP(Conferencistas[[#This Row],[Nombre Completo]],Seminarios[Conferencista 2],Seminarios[Seminario],_xlfn.XLOOKUP(Conferencistas[[#This Row],[Nombre Completo]],Seminarios[Conferencista 3],Seminarios[Seminario],_xlfn.XLOOKUP(Conferencistas[[#This Row],[Nombre Completo]],Seminarios[Conferencista 4],Seminarios[Seminario],_xlfn.XLOOKUP(Conferencistas[[#This Row],[Nombre Completo]],Seminarios[Conferencista 5],Seminarios[Seminario]))))) -> Visiting Scholars 3 | K4: =_xlfn.XLOOKUP(Conferencistas[[#This Row],[Seminario que dirigió]],Seminarios[Seminario],Seminarios[Año]) -> 2024
A5: Niels | B5: Van Quaquebeke | C5: =_xlfn.CONCAT(Conferencistas[[#This Row],[Nombre]]," ",Conferencistas[[#This Row],[Apellido]]) -> Niels Van Quaquebeke | D5: Male | E5: Alemania | F5: 1977 | G5: Kuhne Logistics University - KLU | H5: Alemania | I5: Europe | J5: =_xlfn.XLOOKUP(Conferencistas[[#This Row],[Nombre Completo]],Seminarios[Conferencista 1],Seminarios[Seminario],_xlfn.XLOOKUP(Conferencistas[[#This Row],[Nombre Completo]],Seminarios[Conferencista 2],Seminarios[Seminario],_xlfn.XLOOKUP(Conferencistas[[#This Row],[Nombre Completo]],Seminarios[Conferencista 3],Seminarios[Seminario],_xlfn.XLOOKUP(Conferencistas[[#This Row],[Nombre Completo]],Seminarios[Conferencista 4],Seminarios[Seminario],_xlfn.XLOOKUP(Conferencistas[[#This Row],[Nombre Completo]],Seminarios[Conferencista 5],Seminarios[Seminario]))))) -> Visiting Scholars 1 | K5: =_xlfn.XLOOKUP(Conferencistas[[#This Row],[Seminario que dirigió]],Seminarios[Seminario],Seminarios[Año]) -> 2024
A6: Claudia | B6: Rebolledo | C6: =_xlfn.CONCAT(Conferencistas[[#This Row],[Nombre]]," ",Conferencistas[[#This Row],[Apellido]]) -> Claudia Rebolledo | D6: Female | E6: Colombia | F6: NA | G6: HEC Montreal | H6: Canada | I6: North America | J6: =_xlfn.XLOOKUP(Conferencistas[[#This Row],[Nombre Completo]],Seminarios[Conferencista 1],Seminarios[Seminario],_xlfn.XLOOKUP(Conferencistas[[#This Row],[Nombre Completo]],Seminarios[Conferencista 2],Seminarios[Seminario],_xlfn.XLOOKUP(Conferencistas[[#This Row],[Nombre Completo]],Seminarios[Conferencista 3],Seminarios[Seminario],_xlfn.XLOOKUP(Conferencistas[[#This Row],[Nombre Completo]],Seminarios[Conferencista 4],Seminarios[Seminario],_xlfn.XLOOKUP(Conferencistas[[#This Row],[Nombre Completo]],Seminarios[Conferencista 5],Seminarios[Seminario]))))) -> Ágora 1 | K6: =_xlfn.XLOOKUP(Conferencistas[[#This Row],[Seminario que dirigió]],Seminarios[Seminario],Seminarios[Año]) -> 2024
A7: John | B7: Thøgersen | C7: =_xlfn.CONCAT(Conferencistas[[#This Row],[Nombre]]," ",Conferencistas[[#This Row],[Apellido]]) -> John Thøgersen | D7: Male | E7: Dinamarca | F7: 20263 | G7: Aahus University, Denmark | H7: Dinamarca | I7: Europe | J7: =_xlfn.XLOOKUP(Conferencistas[[#This Row],[Nombre Completo]],Seminarios[Conferencista 1],Seminarios[Seminario],_xlfn.XLOOKUP(Conferencistas[[#This Row],[Nombre Completo]],Seminarios[Conferencista 2],Seminarios[Seminario],_xlfn.XLOOKUP(Conferencistas[[#This Row],[Nombre Completo]],Seminarios[Conferencista 3],Seminarios[Seminario],_xlfn.XLOOKUP(Conferencistas[[#This Row],[Nombre Completo]],Seminarios[Conferencista 4],Seminarios[Seminario],_xlfn.XLOOKUP(Conferencistas[[#This Row],[Nombre Completo]],Seminarios[Conferencista 5],Seminarios[Seminario]))))) -> Ágora 2 | K7: =_xlfn.XLOOKUP(Conferencistas[[#This Row],[Seminario que dirigió]],Seminarios[Seminario],Seminarios[Año]) -> 2024
A8: Barbara | B8: Culiberg | C8: =_xlfn.CONCAT(Conferencistas[[#This Row],[Nombre]]," ",Conferencistas[[#This Row],[Apellido]]) -> Barbara Culiberg | D8: Female | E8: Eslovenia | F8: 29565 | G8: University of Ljubljana, School of Economics and Business | H8: Eslovenia | I8: Europe | J8: =_xlfn.XLOOKUP(Conferencistas[[#This Row],[Nombre Completo]],Seminarios[Conferencista 1],Seminarios[Seminario],_xlfn.XLOOKUP(Conferencistas[[#This Row],[Nombre Completo]],Seminarios[Conferencista 2],Seminarios[Seminario],_xlfn.XLOOKUP(Conferencistas[[#This Row],[Nombre Completo]],Seminarios[Conferencista 3],Seminarios[Seminario],_xlfn.XLOOKUP(Conferencistas[[#This Row],[Nombre Completo]],Seminarios[Conferencista 4],Seminarios[Seminario],_xlfn.XLOOKUP(Conferencistas[[#This Row],[Nombre Completo]],Seminarios[Conferencista 5],Seminarios[Seminario]))))) -> Visiting Scholars 5 | K8: =_xlfn.XLOOKUP(Conferencistas[[#This Row],[Seminario que dirigió]],Seminarios[Seminario],Seminarios[Año]) -> 2024
A9: Janina | B9: Grabs | C9: =_xlfn.CONCAT(Conferencistas[[#This Row],[Nombre]]," ",Conferencistas[[#This Row],[Apellido]]) -> Janina Grabs | D9: Female | E9: Alemania | F9: 32726 | G9: ESADE Business School | H9: España | I9: Europe | J9: =_xlfn.XLOOKUP(Conferencistas[[#This Row],[Nombre Completo]],Seminarios[Conferencista 1],Seminarios[Seminario],_xlfn.XLOOKUP(Conferencistas[[#This Row],[Nombre Completo]],Seminarios[Conferencista 2],Seminarios[Seminario],_xlfn.XLOOKUP(Conferencistas[[#This Row],[Nombre Completo]],Seminarios[Conferencista 3],Seminarios[Seminario],_xlfn.XLOOKUP(Conferencistas[[#This Row],[Nombre Completo]],Seminarios[Conferencista 4],Seminarios[Seminario],_xlfn.XLOOKUP(Conferencistas[[#This Row],[Nombre Completo]],Seminarios[Conferencista 5],Seminarios[Seminario]))))) -> Visiting Scholars 6 | K9: =_xlfn.XLOOKUP(Conferencistas[[#This Row],[Seminario que dirigió]],Seminarios[Seminario],Seminarios[Año]) -> 2024
A10: Rita | B10: Motta | C10: =_xlfn.CONCAT(Conferencistas[[#This Row],[Nombre]]," ",Conferencistas[[#This Row],[Apellido]]) -> Rita Motta | D10: Female | E10: Portugal | F10: 31395 | G10: ESADE Business School | H10: España | I10: Europe | J10: =_xlfn.XLOOKUP(Conferencistas[[#This Row],[Nombre Completo]],Seminarios[Conferencista 1],Seminarios[Seminario],_xlfn.XLOOKUP(Conferencistas[[#This Row],[Nombre Completo]],Seminarios[Conferencista 2],Seminarios[Seminario],_xlfn.XLOOKUP(Conferencistas[[#This Row],[Nombre Completo]],Seminarios[Conferencista 3],Seminarios[Seminario],_xlfn.XLOOKUP(Conferencistas[[#This Row],[Nombre Completo]],Seminarios[Conferencista 4],Seminarios[Seminario],_xlfn.XLOOKUP(Conferencistas[[#This Row],[Nombre Completo]],Seminarios[Conferencista 5],Seminarios[Seminario]))))) -> Visiting Scholars 6 | K10: =_xlfn.XLOOKUP(Conferencistas[[#This Row],[Seminario que dirigió]],Seminarios[Seminario],Seminarios[Año]) -> 2024
A11: Marco | B11: Palacios | C11: =_xlfn.CONCAT(Conferencistas[[#This Row],[Nombre]]," ",Conferencistas[[#This Row],[Apellido]]) -> Marco Palacios | D11: Male | E11: Colombia | F11: 16236 | G11: University of Oxford | H11: Estados Unidos | I11: North America | J11: =_xlfn.XLOOKUP(Conferencistas[[#This Row],[Nombre Completo]],Seminarios[Conferencista 1],Seminarios[Seminario],_xlfn.XLOOKUP(Conferencistas[[#This Row],[Nombre Completo]],Seminarios[Conferencista 2],Seminarios[Seminario],_xlfn.XLOOKUP(Conferencistas[[#This Row],[Nombre Completo]],Seminarios[Conferencista 3],Seminarios[Seminario],_xlfn.XLOOKUP(Conferencistas[[#This Row],[Nombre Completo]],Seminarios[Conferencista 4],Seminarios[Seminario],_xlfn.XLOOKUP(Conferencistas[[#This Row],[Nombre Completo]],Seminarios[Conferencista 5],Seminarios[Seminario]))))) -> Ágora 3 | K11: =_xlfn.XLOOKUP(Conferencistas[[#This Row],[Seminario que dirigió]],Seminarios[Seminario],Seminarios[Año]) -> 2024
A12: Luis Fernando | B12: Molina | C12: =_xlfn.CONCAT(Conferencistas[[#This Row],[Nombre]]," ",Conferencistas[[#This Row],[Apellido]]) -> Luis Fernando Molina | D12: Male | E12: Colombia | F12: NA | G12: Universidad de los Andes | H12: Colombia | I12: South America | J12: =_xlfn.XLOOKUP(Conferencistas[[#This Row],[Nombre Completo]],Seminarios[Conferencista 1],Seminarios[Seminario],_xlfn.XLOOKUP(Conferencistas[[#This Row],[Nombre Completo]],Seminarios[Conferencista 2],Seminarios[Seminario],_xlfn.XLOOKUP(Conferencistas[[#This Row],[Nombre Completo]],Seminarios[Conferencista 3],Seminarios[Seminario],_xlfn.XLOOKUP(Conferencistas[[#This Row],[Nombre Completo]],Seminarios[Conferencista 4],Seminarios[Seminario],_xlfn.XLOOKUP(Conferencistas[[#This Row],[Nombre Completo]],Seminarios[Conferencista 5],Seminarios[Seminario]))))) -> GHE 1 | K12: =_xlfn.XLOOKUP(Conferencistas[[#This Row],[Seminario que dirigió]],Seminarios[Seminario],Seminarios[Año]) -> 2024
A13: Orlando | B13: Grisales | C13: =_xlfn.CONCAT(Conferencistas[[#This Row],[Nombre]]," ",Conferencistas[[#This Row],[Apellido]]) -> Orlando Grisales | D13: Male | E13: Colombia | F13: NA | G13: Investigador Independiente Ottawa | H13: Canada | I13: North America | J13: =_xlfn.XLOOKUP(Conferencistas[[#This Row],[Nombre Completo]],Seminarios[Conferencista 1],Seminarios[Seminario],_xlfn.XLOOKUP(Conferencistas[[#This Row],[Nombre Completo]],Seminarios[Conferencista 2],Seminarios[Seminario],_xlfn.XLOOKUP(Conferencistas[[#This Row],[Nombre Completo]],Seminarios[Conferencista 3],Seminarios[Seminario],_xlfn.XLOOKUP(Conferencistas[[#This Row],[Nombre Completo]],Seminarios[Conferencista 4],Seminarios[Seminario],_xlfn.XLOOKUP(Conferencistas[[#This Row],[Nombre Completo]],Seminarios[Conferencista 5],Seminarios[Seminario]))))) -> GHE 2 | K13: =_xlfn.XLOOKUP(Conferencistas[[#This Row],[Seminario que dirigió]],Seminarios[Seminario],Seminarios[Año]) -> 2024
A14: Alan | B14: Knight | C14: =_xlfn.CONCAT(Conferencistas[[#This Row],[Nombre]]," ",Conferencistas[[#This Row],[Apellido]]) -> Alan Knight | D14: Male | E14: UK | F14: NA | G14: University of Oxford | H14: Inglaterra | I14: Europe | J14: =_xlfn.XLOOKUP(Conferencistas[[#This Row],[Nombre Completo]],Seminarios[Conferencista 1],Seminarios[Seminario],_xlfn.XLOOKUP(Conferencistas[[#This Row],[Nombre Completo]],Seminarios[Conferencista 2],Seminarios[Seminario],_xlfn.XLOOKUP(Conferencistas[[#This Row],[Nombre Completo]],Seminarios[Conferencista 3],Seminarios[Seminario],_xlfn.XLOOKUP(Conferencistas[[#This Row],[Nombre Completo]],Seminarios[Conferencista 4],Seminarios[Seminario],_xlfn.XLOOKUP(Conferencistas[[#This Row],[Nombre Completo]],Seminarios[Conferencista 5],Seminarios[Seminario]))))) -> GHE 3 | K14: =_xlfn.XLOOKUP(Conferencistas[[#This Row],[Seminario que dirigió]],Seminarios[Seminario],Seminarios[Año]) -> 2024
A15: David | B15: Lingelbach | C15: =_xlfn.CONCAT(Conferencistas[[#This Row],[Nombre]]," ",Conferencistas[[#This Row],[Apellido]]) -> David Lingelbach | D15: Male | E15: Estados Unidos | F15: NA | G15: University of Baltimore | H15: Estados Unidos | I15: North America | J15: =_xlfn.XLOOKUP(Conferencistas[[#This Row],[Nombre Completo]],Seminarios[Conferencista 1],Seminarios[Seminario],_xlfn.XLOOKUP(Conferencistas[[#This Row],[Nombre Completo]],Seminarios[Conferencista 2],Seminarios[Seminario],_xlfn.XLOOKUP(Conferencistas[[#This Row],[Nombre Completo]],Seminarios[Conferencista 3],Seminarios[Seminario],_xlfn.XLOOKUP(Conferencistas[[#This Row],[Nombre Completo]],Seminarios[Conferencista 4],Seminarios[Seminario],_xlfn.XLOOKUP(Conferencistas[[#This Row],[Nombre Completo]],Seminarios[Conferencista 5],Seminarios[Seminario]))))) -> Oligarchs - David L. | K15: =_xlfn.XLOOKUP(Conferencistas[[#This Row],[Seminario que dirigió]],Seminarios[Seminario],Seminarios[Año]) -> 2024
A16: Juliana | B16: Moreira Batista | C16: =_xlfn.CONCAT(Conferencistas[[#This Row],[Nombre]]," ",Conferencistas[[#This Row],[Apellido]]) -> Juliana Moreira Batista | D16: Female | E16: Brazil | F16: NA | G16: FGV - Fundação Getulio Vargas | H16: Brasil | I16: South America | J16: =_xlfn.XLOOKUP(Conferencistas[[#This Row],[Nombre Completo]],Seminarios[Conferencista 1],Seminarios[Seminario],_xlfn.XLOOKUP(Conferencistas[[#This Row],[Nombre Completo]],Seminarios[Conferencista 2],Seminarios[Seminario],_xlfn.XLOOKUP(Conferencistas[[#This Row],[Nombre Completo]],Seminarios[Conferencista 3],Seminarios[Seminario],_xlfn.XLOOKUP(Conferencistas[[#This Row],[Nombre Completo]],Seminarios[Conferencista 4],Seminarios[Seminario],_xlfn.XLOOKUP(Conferencistas[[#This Row],[Nombre Completo]],Seminarios[Conferencista 5],Seminarios[Seminario]))))) -> Recruitment research 1 | K16: =_xlfn.XLOOKUP(Conferencistas[[#This Row],[Seminario que dirigió]],Seminarios[Seminario],Seminarios[Año]) -> 2024
A17: Eduardo | B17: Posada Carbó | C17: =_xlfn.CONCAT(Conferencistas[[#This Row],[Nombre]]," ",Conferencistas[[#This Row],[Apellido]]) -> Eduardo Posada Carbó | D17: Male | E17: Colombia | F17: 1956 | G17: University of Oxford | H17: Inglaterra | I17: Europe | J17: =_xlfn.XLOOKUP(Conferencistas[[#This Row],[Nombre Completo]],Seminarios[Conferencista 1],Seminarios[Seminario],_xlfn.XLOOKUP(Conferencistas[[#This Row],[Nombre Completo]],Seminarios[Conferencista 2],Seminarios[Seminario],_xlfn.XLOOKUP(Conferencistas[[#This Row],[Nombre Completo]],Seminarios[Conferencista 3],Seminarios[Seminario],_xlfn.XLOOKUP(Conferencistas[[#This Row],[Nombre Completo]],Seminarios[Conferencista 4],Seminarios[Seminario],_xlfn.XLOOKUP(Conferencistas[[#This Row],[Nombre Completo]],Seminarios[Conferencista 5],Seminarios[Seminario]))))) -> GHE 4 | K17: =_xlfn.XLOOKUP(Conferencistas[[#This Row],[Seminario que dirigió]],Seminarios[Seminario],Seminarios[Año]) -> 2024
A18: Luis Gabriel | B18: Galán | C18: =_xlfn.CONCAT(Conferencistas[[#This Row],[Nombre]]," ",Conferencistas[[#This Row],[Apellido]]) -> Luis Gabriel Galán | D18: Male | E18: Colombia | F18: NA | G18: Universidad de los Andes | H18: Colombia | I18: South America | J18: =_xlfn.XLOOKUP(Conferencistas[[#This Row],[Nombre Completo]],Seminarios[Conferencista 1],Seminarios[Seminario],_xlfn.XLOOKUP(Conferencistas[[#This Row],[Nombre Completo]],Seminarios[Conferencista 2],Seminarios[Seminario],_xlfn.XLOOKUP(Conferencistas[[#This Row],[Nombre Completo]],Seminarios[Conferencista 3],Seminarios[Seminario],_xlfn.XLOOKUP(Conferencistas[[#This Row],[Nombre Completo]],Seminarios[Conferencista 4],Seminarios[Seminario],_xlfn.XLOOKUP(Conferencistas[[#This Row],[Nombre Completo]],Seminarios[Conferencista 5],Seminarios[Seminario]))))) -> GHE 4 | K18: =_xlfn.XLOOKUP(Conferencistas[[#This Row],[Seminario que dirigió]],Seminarios[Seminario],Seminarios[Año]) -> 2024
A19: James V. | B19: Torres Moreno | C19: =_xlfn.CONCAT(Conferencistas[[#This Row],[Nombre]]," ",Conferencistas[[#This Row],[Apellido]]) -> James V. Torres Moreno | D19: Male | E19: Colombia | F19: NA | G19: Universidad de los Andes | H19: Colombia | I19: South America | J19: =_xlfn.XLOOKUP(Conferencistas[[#This Row],[Nombre Completo]],Seminarios[Conferencista 1],Seminarios[Seminario],_xlfn.XLOOKUP(Conferencistas[[#This Row],[Nombre Completo]],Seminarios[Conferencista 2],Seminarios[Seminario],_xlfn.XLOOKUP(Conferencistas[[#This Row],[Nombre Completo]],Seminarios[Conferencista 3],Seminarios[Seminario],_xlfn.XLOOKUP(Conferencistas[[#This Row],[Nombre Completo]],Seminarios[Conferencista 4],Seminarios[Seminario],_xlfn.XLOOKUP(Conferencistas[[#This Row],[Nombre Completo]],Seminarios[Conferencista 5],Seminarios[Seminario]))))) -> GHE 4 | K19: =_xlfn.XLOOKUP(Conferencistas[[#This Row],[Seminario que dirigió]],Seminarios[Seminario],Seminarios[Año]) -> 2024
