Workbook

Sheet Información a reportar
B2: BASES DE DATOS MOVILIDAD INCOMING Y OUTGOING FACULTAD DE ADMINISTRACIÓN
B4: Información solicitada:
B6: Movildiad Outgoing | H6: Movildiad Incoming
B7: Requerimos todos los datos y detalles de los estudiantes que finalmente tuvieron movilidad internacional Outgoing y fueron postulados por la Facultad de Administración | H7: Requerimos todos los datos y detalles de los estudiantes extranjeros que fueron nominados a la Facultad de Administración, y tomaron como mínimo 1 curso de Administración
B11: Campos requeridos obligatorios | H11: Campos requeridos obligatorios
B12: Datos estudiantes | E12: Correo electrónico | H12: Datos estudiantes | K12: Código
E13: Código Uniandes | K13: Nombre
E14: First name | K14: Apellido
E15: Surname | K15: Cuenta Alterna
E16: Nombre completo | K16: Cuenta Uniandes
B17: Detalles académicos | E17: Programa1 | H17: Detalles procedencia | K17: Año
E18: Facultad1 | K18: Semestre de Movilidad
E19: Programa2 | K19: Universidad
E20: Facultad2 | K20: País
B21: Detalles postulación | E21: Año de Movilidad | K21: Tipo de Movilidad
E22: Período de Movilidad | H22: Detalles nominación | K22: Programa Nominación | M22: Es muy importante saber el programa al que se nominó el estudiante
E23: Convocatoria | K23: Nivel Nominación
E24: Tipo de Movilidad
E25: Nivel
E26: Programa Postulación
E27: Facultad de Postulación
E28: Universidad
E29: País
B31: Periodo solicitud información movilidad Primer Semestre
B32: Finales de junio para las convocatorias -10
B33: Periodo solicitud información movilidad Segundo Semestre
B34: Finales de enero para las convocatorias -20

Sheet Utilización Convenios
C2: UNDERGRADUATED EXCHANGE
E3: 2020 | G3: 2021 | I3: 2022 | K3: 2023 | M3: 2024 | O3: 2025 | Q3: Total
C4: Universidad KPIs | D4: País | E4: Outgoing | F4: Incoming | G4: Outgoing | H4: Incoming | I4: Outgoing | J4: Incoming | K4: Outgoing | L4: Incoming | M4: Outgoing | N4: Incoming | O4: Outgoing | P4: Incoming | Q4: Outgoing | R4: Incoming
B5: C O N V E N I O S E S P E C Í F I C O S | C5: A.B. Freeman School of Business, Tulane University | D5: United States | E5: =COUNTIFS(Tabla1[Tipo de Movilidad],"Intercambio*",Tabla1[Universidad KPIs],'Utilización Convenios'!$C5,Tabla1[Año de Movilidad],'Utilización Convenios'!E$3,Tabla1[Nivel],"Pregrado") -> 1 | F5: =COUNTIFS(Tabla2[Tipo de Movilidad],"Intercambio*",Tabla2[Universidad KPIs],'Utilización Convenios'!$C5,Tabla2[Año],'Utilización Convenios'!E$3,Tabla2[Nivel Nominación],"Undergraduate / Bachelor") -> 2 | G5: =COUNTIFS(Tabla1[Tipo de Movilidad],"Intercambio*",Tabla1[Universidad KPIs],'Utilización Convenios'!$C5,Tabla1[Año de Movilidad],'Utilización Convenios'!G$3,Tabla1[Nivel],"Pregrado") -> 2 | H5: =COUNTIFS(Tabla2[Tipo de Movilidad],"Intercambio*",Tabla2[Universidad KPIs],'Utilización Convenios'!$C5,Tabla2[Año],'Utilización Convenios'!G$3,Tabla2[Nivel Nominación],"Undergraduate / Bachelor") -> 0 | I5: =COUNTIFS(Tabla1[Tipo de Movilidad],"Intercambio*",Tabla1[Universidad KPIs],'Utilización Convenios'!$C5,Tabla1[Año de Movilidad],'Utilización Convenios'!I$3,Tabla1[Nivel],"Pregrado") -> 4 | J5: =COUNTIFS(Tabla2[Tipo de Movilidad],"Intercambio*",Tabla2[Universidad KPIs],'Utilización Convenios'!$C5,Tabla2[Año],'Utilización Convenios'!I$3,Tabla2[Nivel Nominación],"Undergraduate / Bachelor") -> 5 | K5: =COUNTIFS(Tabla1[Tipo de Movilidad],"Intercambio*",Tabla1[Universidad KPIs],'Utilización Convenios'!$C5,Tabla1[Año de Movilidad],'Utilización Convenios'!K$3,Tabla1[Nivel],"Pregrado") -> 5 | L5: =COUNTIFS(Tabla2[Tipo de Movilidad],"Intercambio*",Tabla2[Universidad KPIs],'Utilización Convenios'!$C5,Tabla2[Año],'Utilización Convenios'!K$3,Tabla2[Nivel Nominación],"Undergraduate / Bachelor") -> 3 | M5: =COUNTIFS(Tabla1[Tipo de Movilidad],"Intercambio*",Tabla1[Universidad KPIs],'Utilización Convenios'!$C5,Tabla1[Año de Movilidad],'Utilización Convenios'!M$3,Tabla1[Nivel],"Pregrado") -> 1 | N5: =COUNTIFS(Tabla2[Tipo de Movilidad],"Intercambio*",Tabla2[Universidad KPIs],'Utilización Convenios'!$C5,Tabla2[Año],'Utilización Convenios'!M$3,Tabla2[Nivel Nominación],"Undergraduate / Bachelor") -> 2 | O5: =COUNTIFS(Tabla1[Tipo de Movilidad],"Intercambio*",Tabla1[Universidad KPIs],'Utilización Convenios'!$C5,Tabla1[Año de Movilidad],'Utilización Convenios'!O$3,Tabla1[Nivel],"Pregrado") -> 1 | P5: =COUNTIFS(Tabla2[Tipo de Movilidad],"Intercambio*",Tabla2[Universidad KPIs],'Utilización Convenios'!$C5,Tabla2[Año],'Utilización Convenios'!O$3,Tabla2[Nivel Nominación],"Undergraduate / Bachelor") -> 3 | Q5: =SUMIF($E$4:$P$4,Q$4,$E5:$P5) -> 14 | R5: =SUMIF($E$4:$P$4,R$4,$E5:$P5) -> 15
C6: Aalto University | D6: Finland | E6: =COUNTIFS(Tabla1[Tipo de Movilidad],"Intercambio*",Tabla1[Universidad KPIs],'Utilización Convenios'!$C6,Tabla1[Año de Movilidad],'Utilización Convenios'!E$3,Tabla1[Nivel],"Pregrado") -> 1 | F6: =COUNTIFS(Tabla2[Tipo de Movilidad],"Intercambio*",Tabla2[Universidad KPIs],'Utilización Convenios'!$C6,Tabla2[Año],'Utilización Convenios'!E$3,Tabla2[Nivel Nominación],"Undergraduate / Bachelor") -> 0 | G6: =COUNTIFS(Tabla1[Tipo de Movilidad],"Intercambio*",Tabla1[Universidad KPIs],'Utilización Convenios'!$C6,Tabla1[Año de Movilidad],'Utilización Convenios'!G$3,Tabla1[Nivel],"Pregrado") -> 1 | H6: =COUNTIFS(Tabla2[Tipo de Movilidad],"Intercambio*",Tabla2[Universidad KPIs],'Utilización Convenios'!$C6,Tabla2[Año],'Utilización Convenios'!G$3,Tabla2[Nivel Nominación],"Undergraduate / Bachelor") -> 1 | I6: =COUNTIFS(Tabla1[Tipo de Movilidad],"Intercambio*",Tabla1[Universidad KPIs],'Utilización Convenios'!$C6,Tabla1[Año de Movilidad],'Utilización Convenios'!I$3,Tabla1[Nivel],"Pregrado") -> 0 | J6: =COUNTIFS(Tabla2[Tipo de Movilidad],"Intercambio*",Tabla2[Universidad KPIs],'Utilización Convenios'!$C6,Tabla2[Año],'Utilización Convenios'!I$3,Tabla2[Nivel Nominación],"Undergraduate / Bachelor") -> 0 | K6: =COUNTIFS(Tabla1[Tipo de Movilidad],"Intercambio*",Tabla1[Universidad KPIs],'Utilización Convenios'!$C6,Tabla1[Año de Movilidad],'Utilización Convenios'!K$3,Tabla1[Nivel],"Pregrado") -> 2 | L6: =COUNTIFS(Tabla2[Tipo de Movilidad],"Intercambio*",Tabla2[Universidad KPIs],'Utilización Convenios'!$C6,Tabla2[Año],'Utilización Convenios'!K$3,Tabla2[Nivel Nominación],"Undergraduate / Bachelor") -> 1 | M6: =COUNTIFS(Tabla1[Tipo de Movilidad],"Intercambio*",Tabla1[Universidad KPIs],'Utilización Convenios'!$C6,Tabla1[Año de Movilidad],'Utilización Convenios'!M$3,Tabla1[Nivel],"Pregrado") -> 0 | N6: =COUNTIFS(Tabla2[Tipo de Movilidad],"Intercambio*",Tabla2[Universidad KPIs],'Utilización Convenios'!$C6,Tabla2[Año],'Utilización Convenios'!M$3,Tabla2[Nivel Nominación],"Undergraduate / Bachelor") -> 1 | O6: =COUNTIFS(Tabla1[Tipo de Movilidad],"Intercambio*",Tabla1[Universidad KPIs],'Utilización Convenios'!$C6,Tabla1[Año de Movilidad],'Utilización Convenios'!O$3,Tabla1[Nivel],"Pregrado") -> 1 | P6: =COUNTIFS(Tabla2[Tipo de Movilidad],"Intercambio*",Tabla2[Universidad KPIs],'Utilización Convenios'!$C6,Tabla2[Año],'Utilización Convenios'!O$3,Tabla2[Nivel Nominación],"Undergraduate / Bachelor") -> 0 | Q6: =SUMIF($E$4:$P$4,Q$4,$E6:$P6) -> 5 | R6: =SUMIF($E$4:$P$4,R$4,$E6:$P6) -> 3
C7: Aston University | D7: United Kingdom | E7: =COUNTIFS(Tabla1[Tipo de Movilidad],"Intercambio*",Tabla1[Universidad KPIs],'Utilización Convenios'!$C7,Tabla1[Año de Movilidad],'Utilización Convenios'!E$3,Tabla1[Nivel],"Pregrado") -> 2 | F7: =COUNTIFS(Tabla2[Tipo de Movilidad],"Intercambio*",Tabla2[Universidad KPIs],'Utilización Convenios'!$C7,Tabla2[Año],'Utilización Convenios'!E$3,Tabla2[Nivel Nominación],"Undergraduate / Bachelor") -> 1 | G7: =COUNTIFS(Tabla1[Tipo de Movilidad],"Intercambio*",Tabla1[Universidad KPIs],'Utilización Convenios'!$C7,Tabla1[Año de Movilidad],'Utilización Convenios'!G$3,Tabla1[Nivel],"Pregrado") -> 2 | H7: =COUNTIFS(Tabla2[Tipo de Movilidad],"Intercambio*",Tabla2[Universidad KPIs],'Utilización Convenios'!$C7,Tabla2[Año],'Utilización Convenios'!G$3,Tabla2[Nivel Nominación],"Undergraduate / Bachelor") -> 0 | I7: =COUNTIFS(Tabla1[Tipo de Movilidad],"Intercambio*",Tabla1[Universidad KPIs],'Utilización Convenios'!$C7,Tabla1[Año de Movilidad],'Utilización Convenios'!I$3,Tabla1[Nivel],"Pregrado") -> 2 | J7: =COUNTIFS(Tabla2[Tipo de Movilidad],"Intercambio*",Tabla2[Universidad KPIs],'Utilización Convenios'!$C7,Tabla2[Año],'Utilización Convenios'!I$3,Tabla2[Nivel Nominación],"Undergraduate / Bachelor") -> 0 | K7: =COUNTIFS(Tabla1[Tipo de Movilidad],"Intercambio*",Tabla1[Universidad KPIs],'Utilización Convenios'!$C7,Tabla1[Año de Movilidad],'Utilización Convenios'!K$3,Tabla1[Nivel],"Pregrado") -> 3 | L7: =COUNTIFS(Tabla2[Tipo de Movilidad],"Intercambio*",Tabla2[Universidad KPIs],'Utilización Convenios'!$C7,Tabla2[Año],'Utilización Convenios'!K$3,Tabla2[Nivel Nominación],"Undergraduate / Bachelor") -> 0 | M7: =COUNTIFS(Tabla1[Tipo de Movilidad],"Intercambio*",Tabla1[Universidad KPIs],'Utilización Convenios'!$C7,Tabla1[Año de Movilidad],'Utilización Convenios'!M$3,Tabla1[Nivel],"Pregrado") -> 2 | N7: =COUNTIFS(Tabla2[Tipo de Movilidad],"Intercambio*",Tabla2[Universidad KPIs],'Utilización Convenios'!$C7,Tabla2[Año],'Utilización Convenios'!M$3,Tabla2[Nivel Nominación],"Undergraduate / Bachelor") -> 0 | O7: =COUNTIFS(Tabla1[Tipo de Movilidad],"Intercambio*",Tabla1[Universidad KPIs],'Utilización Convenios'!$C7,Tabla1[Año de Movilidad],'Utilización Convenios'!O$3,Tabla1[Nivel],"Pregrado") -> 1 | P7: =COUNTIFS(Tabla2[Tipo de Movilidad],"Intercambio*",Tabla2[Universidad KPIs],'Utilización Convenios'!$C7,Tabla2[Año],'Utilización Convenios'!O$3,Tabla2[Nivel Nominación],"Undergraduate / Bachelor") -> 0 | Q7: =SUMIF($E$4:$P$4,Q$4,$E7:$P7) -> 12 | R7: =SUMIF($E$4:$P$4,R$4,$E7:$P7) -> 1
C8: Audencia. École de Management | D8: France | E8: =COUNTIFS(Tabla1[Tipo de Movilidad],"Intercambio*",Tabla1[Universidad KPIs],'Utilización Convenios'!$C8,Tabla1[Año de Movilidad],'Utilización Convenios'!E$3,Tabla1[Nivel],"Pregrado") -> 1 | F8: =COUNTIFS(Tabla2[Tipo de Movilidad],"Intercambio*",Tabla2[Universidad KPIs],'Utilización Convenios'!$C8,Tabla2[Año],'Utilización Convenios'!E$3,Tabla2[Nivel Nominación],"Undergraduate / Bachelor") -> 2 | G8: =COUNTIFS(Tabla1[Tipo de Movilidad],"Intercambio*",Tabla1[Universidad KPIs],'Utilización Convenios'!$C8,Tabla1[Año de Movilidad],'Utilización Convenios'!G$3,Tabla1[Nivel],"Pregrado") -> 1 | H8: =COUNTIFS(Tabla2[Tipo de Movilidad],"Intercambio*",Tabla2[Universidad KPIs],'Utilización Convenios'!$C8,Tabla2[Año],'Utilización Convenios'!G$3,Tabla2[Nivel Nominación],"Undergraduate / Bachelor") -> 1 | I8: =COUNTIFS(Tabla1[Tipo de Movilidad],"Intercambio*",Tabla1[Universidad KPIs],'Utilización Convenios'!$C8,Tabla1[Año de Movilidad],'Utilización Convenios'!I$3,Tabla1[Nivel],"Pregrado") -> 2 | J8: =COUNTIFS(Tabla2[Tipo de Movilidad],"Intercambio*",Tabla2[Universidad KPIs],'Utilización Convenios'!$C8,Tabla2[Año],'Utilización Convenios'!I$3,Tabla2[Nivel Nominación],"Undergraduate / Bachelor") -> 3 | K8: =COUNTIFS(Tabla1[Tipo de Movilidad],"Intercambio*",Tabla1[Universidad KPIs],'Utilización Convenios'!$C8,Tabla1[Año de Movilidad],'Utilización Convenios'!K$3,Tabla1[Nivel],"Pregrado") -> 3 | L8: =COUNTIFS(Tabla2[Tipo de Movilidad],"Intercambio*",Tabla2[Universidad KPIs],'Utilización Convenios'!$C8,Tabla2[Año],'Utilización Convenios'!K$3,Tabla2[Nivel Nominación],"Undergraduate / Bachelor") -> 4 | M8: =COUNTIFS(Tabla1[Tipo de Movilidad],"Intercambio*",Tabla1[Universidad KPIs],'Utilización Convenios'!$C8,Tabla1[Año de Movilidad],'Utilización Convenios'!M$3,Tabla1[Nivel],"Pregrado") -> 1 | N8: =COUNTIFS(Tabla2[Tipo de Movilidad],"Intercambio*",Tabla2[Universidad KPIs],'Utilización Convenios'!$C8,Tabla2[Año],'Utilización Convenios'!M$3,Tabla2[Nivel Nominación],"Undergraduate / Bachelor") -> 2 | O8: =COUNTIFS(Tabla1[Tipo de Movilidad],"Intercambio*",Tabla1[Universidad KPIs],'Utilización Convenios'!$C8,Tabla1[Año de Movilidad],'Utilización Convenios'!O$3,Tabla1[Nivel],"Pregrado") -> 1 | P8: =COUNTIFS(Tabla2[Tipo de Movilidad],"Intercambio*",Tabla2[Universidad KPIs],'Utilización Convenios'!$C8,Tabla2[Año],'Utilización Convenios'!O$3,Tabla2[Nivel Nominación],"Undergraduate / Bachelor") -> 1 | Q8: =SUMIF($E$4:$P$4,Q$4,$E8:$P8) -> 9 | R8: =SUMIF($E$4:$P$4,R$4,$E8:$P8) -> 13
C9: BI Norwegian Business School | D9: Norway | E9: =COUNTIFS(Tabla1[Tipo de Movilidad],"Intercambio*",Tabla1[Universidad KPIs],'Utilización Convenios'!$C9,Tabla1[Año de Movilidad],'Utilización Convenios'!E$3,Tabla1[Nivel],"Pregrado") -> 0 | F9: =COUNTIFS(Tabla2[Tipo de Movilidad],"Intercambio*",Tabla2[Universidad KPIs],'Utilización Convenios'!$C9,Tabla2[Año],'Utilización Convenios'!E$3,Tabla2[Nivel Nominación],"Undergraduate / Bachelor") -> 0 | G9: =COUNTIFS(Tabla1[Tipo de Movilidad],"Intercambio*",Tabla1[Universidad KPIs],'Utilización Convenios'!$C9,Tabla1[Año de Movilidad],'Utilización Convenios'!G$3,Tabla1[Nivel],"Pregrado") -> 0 | H9: =COUNTIFS(Tabla2[Tipo de Movilidad],"Intercambio*",Tabla2[Universidad KPIs],'Utilización Convenios'!$C9,Tabla2[Año],'Utilización Convenios'!G$3,Tabla2[Nivel Nominación],"Undergraduate / Bachelor") -> 0 | I9: =COUNTIFS(Tabla1[Tipo de Movilidad],"Intercambio*",Tabla1[Universidad KPIs],'Utilización Convenios'!$C9,Tabla1[Año de Movilidad],'Utilización Convenios'!I$3,Tabla1[Nivel],"Pregrado") -> 0 | J9: =COUNTIFS(Tabla2[Tipo de Movilidad],"Intercambio*",Tabla2[Universidad KPIs],'Utilización Convenios'!$C9,Tabla2[Año],'Utilización Convenios'!I$3,Tabla2[Nivel Nominación],"Undergraduate / Bachelor") -> 0 | K9: =COUNTIFS(Tabla1[Tipo de Movilidad],"Intercambio*",Tabla1[Universidad KPIs],'Utilización Convenios'!$C9,Tabla1[Año de Movilidad],'Utilización Convenios'!K$3,Tabla1[Nivel],"Pregrado") -> 2 | L9: =COUNTIFS(Tabla2[Tipo de Movilidad],"Intercambio*",Tabla2[Universidad KPIs],'Utilización Convenios'!$C9,Tabla2[Año],'Utilización Convenios'!K$3,Tabla2[Nivel Nominación],"Undergraduate / Bachelor") -> 0 | M9: =COUNTIFS(Tabla1[Tipo de Movilidad],"Intercambio*",Tabla1[Universidad KPIs],'Utilización Convenios'!$C9,Tabla1[Año de Movilidad],'Utilización Convenios'!M$3,Tabla1[Nivel],"Pregrado") -> 2 | N9: =COUNTIFS(Tabla2[Tipo de Movilidad],"Intercambio*",Tabla2[Universidad KPIs],'Utilización Convenios'!$C9,Tabla2[Año],'Utilización Convenios'!M$3,Tabla2[Nivel Nominación],"Undergraduate / Bachelor") -> 0 | O9: =COUNTIFS(Tabla1[Tipo de Movilidad],"Intercambio*",Tabla1[Universidad KPIs],'Utilización Convenios'!$C9,Tabla1[Año de Movilidad],'Utilización Convenios'!O$3,Tabla1[Nivel],"Pregrado") -> 0 | P9: =COUNTIFS(Tabla2[Tipo de Movilidad],"Intercambio*",Tabla2[Universidad KPIs],'Utilización Convenios'!$C9,Tabla2[Año],'Utilización Convenios'!O$3,Tabla2[Nivel Nominación],"Undergraduate / Bachelor") -> 0 | Q9: =SUMIF($E$4:$P$4,Q$4,$E9:$P9) -> 4 | R9: =SUMIF($E$4:$P$4,R$4,$E9:$P9) -> 0
C10: Catolica Lisbon Business & Economics. Universidade Católica Portuguesa | D10: Portugal | E10: =COUNTIFS(Tabla1[Tipo de Movilidad],"Intercambio*",Tabla1[Universidad KPIs],'Utilización Convenios'!$C10,Tabla1[Año de Movilidad],'Utilización Convenios'!E$3,Tabla1[Nivel],"Pregrado") -> 2 | F10: =COUNTIFS(Tabla2[Tipo de Movilidad],"Intercambio*",Tabla2[Universidad KPIs],'Utilización Convenios'!$C10,Tabla2[Año],'Utilización Convenios'!E$3,Tabla2[Nivel Nominación],"Undergraduate / Bachelor") -> 0 | G10: =COUNTIFS(Tabla1[Tipo de Movilidad],"Intercambio*",Tabla1[Universidad KPIs],'Utilización Convenios'!$C10,Tabla1[Año de Movilidad],'Utilización Convenios'!G$3,Tabla1[Nivel],"Pregrado") -> 2 | H10: =COUNTIFS(Tabla2[Tipo de Movilidad],"Intercambio*",Tabla2[Universidad KPIs],'Utilización Convenios'!$C10,Tabla2[Año],'Utilización Convenios'!G$3,Tabla2[Nivel Nominación],"Undergraduate / Bachelor") -> 0 | I10: =COUNTIFS(Tabla1[Tipo de Movilidad],"Intercambio*",Tabla1[Universidad KPIs],'Utilización Convenios'!$C10,Tabla1[Año de Movilidad],'Utilización Convenios'!I$3,Tabla1[Nivel],"Pregrado") -> 4 | J10: =COUNTIFS(Tabla2[Tipo de Movilidad],"Intercambio*",Tabla2[Universidad KPIs],'Utilización Convenios'!$C10,Tabla2[Año],'Utilización Convenios'!I$3,Tabla2[Nivel Nominación],"Undergraduate / Bachelor") -> 1 | K10: =COUNTIFS(Tabla1[Tipo de Movilidad],"Intercambio*",Tabla1[Universidad KPIs],'Utilización Convenios'!$C10,Tabla1[Año de Movilidad],'Utilización Convenios'!K$3,Tabla1[Nivel],"Pregrado") -> 3 | L10: =COUNTIFS(Tabla2[Tipo de Movilidad],"Intercambio*",Tabla2[Universidad KPIs],'Utilización Convenios'!$C10,Tabla2[Año],'Utilización Convenios'!K$3,Tabla2[Nivel Nominación],"Undergraduate / Bachelor") -> 4 | M10: =COUNTIFS(Tabla1[Tipo de Movilidad],"Intercambio*",Tabla1[Universidad KPIs],'Utilización Convenios'!$C10,Tabla1[Año de Movilidad],'Utilización Convenios'!M$3,Tabla1[Nivel],"Pregrado") -> 2 | N10: =COUNTIFS(Tabla2[Tipo de Movilidad],"Intercambio*",Tabla2[Universidad KPIs],'Utilización Convenios'!$C10,Tabla2[Año],'Utilización Convenios'!M$3,Tabla2[Nivel Nominación],"Undergraduate / Bachelor") -> 2 | O10: =COUNTIFS(Tabla1[Tipo de Movilidad],"Intercambio*",Tabla1[Universidad KPIs],'Utilización Convenios'!$C10,Tabla1[Año de Movilidad],'Utilización Convenios'!O$3,Tabla1[Nivel],"Pregrado") -> 2 | P10: =COUNTIFS(Tabla2[Tipo de Movilidad],"Intercambio*",Tabla2[Universidad KPIs],'Utilización Convenios'!$C10,Tabla2[Año],'Utilización Convenios'!O$3,Tabla2[Nivel Nominación],"Undergraduate / Bachelor") -> 0 | Q10: =SUMIF($E$4:$P$4,Q$4,$E10:$P10) -> 15 | R10: =SUMIF($E$4:$P$4,R$4,$E10:$P10) -> 7
C11: CBS- Copenhagen Business School | D11: Denmark | E11: =COUNTIFS(Tabla1[Tipo de Movilidad],"Intercambio*",Tabla1[Universidad KPIs],'Utilización Convenios'!$C11,Tabla1[Año de Movilidad],'Utilización Convenios'!E$3,Tabla1[Nivel],"Pregrado") -> 2 | F11: =COUNTIFS(Tabla2[Tipo de Movilidad],"Intercambio*",Tabla2[Universidad KPIs],'Utilización Convenios'!$C11,Tabla2[Año],'Utilización Convenios'!E$3,Tabla2[Nivel Nominación],"Undergraduate / Bachelor") -> 0 | G11: =COUNTIFS(Tabla1[Tipo de Movilidad],"Intercambio*",Tabla1[Universidad KPIs],'Utilización Convenios'!$C11,Tabla1[Año de Movilidad],'Utilización Convenios'!G$3,Tabla1[Nivel],"Pregrado") -> 2 | H11: =COUNTIFS(Tabla2[Tipo de Movilidad],"Intercambio*",Tabla2[Universidad KPIs],'Utilización Convenios'!$C11,Tabla2[Año],'Utilización Convenios'!G$3,Tabla2[Nivel Nominación],"Undergraduate / Bachelor") -> 1 | I11: =COUNTIFS(Tabla1[Tipo de Movilidad],"Intercambio*",Tabla1[Universidad KPIs],'Utilización Convenios'!$C11,Tabla1[Año de Movilidad],'Utilización Convenios'!I$3,Tabla1[Nivel],"Pregrado") -> 2 | J11: =COUNTIFS(Tabla2[Tipo de Movilidad],"Intercambio*",Tabla2[Universidad KPIs],'Utilización Convenios'!$C11,Tabla2[Año],'Utilización Convenios'!I$3,Tabla2[Nivel Nominación],"Undergraduate / Bachelor") -> 3 | K11: =COUNTIFS(Tabla1[Tipo de Movilidad],"Intercambio*",Tabla1[Universidad KPIs],'Utilización Convenios'!$C11,Tabla1[Año de Movilidad],'Utilización Convenios'!K$3,Tabla1[Nivel],"Pregrado") -> 2 | L11: =COUNTIFS(Tabla2[Tipo de Movilidad],"Intercambio*",Tabla2[Universidad KPIs],'Utilización Convenios'!$C11,Tabla2[Año],'Utilización Convenios'!K$3,Tabla2[Nivel Nominación],"Undergraduate / Bachelor") -> 2 | M11: =COUNTIFS(Tabla1[Tipo de Movilidad],"Intercambio*",Tabla1[Universidad KPIs],'Utilización Convenios'!$C11,Tabla1[Año de Movilidad],'Utilización Convenios'!M$3,Tabla1[Nivel],"Pregrado") -> 1 | N11: =COUNTIFS(Tabla2[Tipo de Movilidad],"Intercambio*",Tabla2[Universidad KPIs],'Utilización Convenios'!$C11,Tabla2[Año],'Utilización Convenios'!M$3,Tabla2[Nivel Nominación],"Undergraduate / Bachelor") -> 1 | O11: =COUNTIFS(Tabla1[Tipo de Movilidad],"Intercambio*",Tabla1[Universidad KPIs],'Utilización Convenios'!$C11,Tabla1[Año de Movilidad],'Utilización Convenios'!O$3,Tabla1[Nivel],"Pregrado") -> 2 | P11: =COUNTIFS(Tabla2[Tipo de Movilidad],"Intercambio*",Tabla2[Universidad KPIs],'Utilización Convenios'!$C11,Tabla2[Año],'Utilización Convenios'!O$3,Tabla2[Nivel Nominación],"Undergraduate / Bachelor") -> 0 | Q11: =SUMIF($E$4:$P$4,Q$4,$E11:$P11) -> 11 | R11: =SUMIF($E$4:$P$4,R$4,$E11:$P11) -> 7
C12: City University of Hong Kong | D12: China | E12: =COUNTIFS(Tabla1[Tipo de Movilidad],"Intercambio*",Tabla1[Universidad KPIs],'Utilización Convenios'!$C12,Tabla1[Año de Movilidad],'Utilización Convenios'!E$3,Tabla1[Nivel],"Pregrado") -> 0 | F12: =COUNTIFS(Tabla2[Tipo de Movilidad],"Intercambio*",Tabla2[Universidad KPIs],'Utilización Convenios'!$C12,Tabla2[Año],'Utilización Convenios'!E$3,Tabla2[Nivel Nominación],"Undergraduate / Bachelor") -> 0 | G12: =COUNTIFS(Tabla1[Tipo de Movilidad],"Intercambio*",Tabla1[Universidad KPIs],'Utilización Convenios'!$C12,Tabla1[Año de Movilidad],'Utilización Convenios'!G$3,Tabla1[Nivel],"Pregrado") -> 0 | H12: =COUNTIFS(Tabla2[Tipo de Movilidad],"Intercambio*",Tabla2[Universidad KPIs],'Utilización Convenios'!$C12,Tabla2[Año],'Utilización Convenios'!G$3,Tabla2[Nivel Nominación],"Undergraduate / Bachelor") -> 0 | I12: =COUNTIFS(Tabla1[Tipo de Movilidad],"Intercambio*",Tabla1[Universidad KPIs],'Utilización Convenios'!$C12,Tabla1[Año de Movilidad],'Utilización Convenios'!I$3,Tabla1[Nivel],"Pregrado") -> 1 | J12: =COUNTIFS(Tabla2[Tipo de Movilidad],"Intercambio*",Tabla2[Universidad KPIs],'Utilización Convenios'!$C12,Tabla2[Año],'Utilización Convenios'!I$3,Tabla2[Nivel Nominación],"Undergraduate / Bachelor") -> 0 | K12: =COUNTIFS(Tabla1[Tipo de Movilidad],"Intercambio*",Tabla1[Universidad KPIs],'Utilización Convenios'!$C12,Tabla1[Año de Movilidad],'Utilización Convenios'!K$3,Tabla1[Nivel],"Pregrado") -> 2 | L12: =COUNTIFS(Tabla2[Tipo de Movilidad],"Intercambio*",Tabla2[Universidad KPIs],'Utilización Convenios'!$C12,Tabla2[Año],'Utilización Convenios'!K$3,Tabla2[Nivel Nominación],"Undergraduate / Bachelor") -> 0 | M12: =COUNTIFS(Tabla1[Tipo de Movilidad],"Intercambio*",Tabla1[Universidad KPIs],'Utilización Convenios'!$C12,Tabla1[Año de Movilidad],'Utilización Convenios'!M$3,Tabla1[Nivel],"Pregrado") -> 0 | N12: =COUNTIFS(Tabla2[Tipo de Movilidad],"Intercambio*",Tabla2[Universidad KPIs],'Utilización Convenios'!$C12,Tabla2[Año],'Utilización Convenios'!M$3,Tabla2[Nivel Nominación],"Undergraduate / Bachelor") -> 0 | O12: =COUNTIFS(Tabla1[Tipo de Movilidad],"Intercambio*",Tabla1[Universidad KPIs],'Utilización Convenios'!$C12,Tabla1[Año de Movilidad],'Utilización Convenios'!O$3,Tabla1[Nivel],"Pregrado") -> 1 | P12: =COUNTIFS(Tabla2[Tipo de Movilidad],"Intercambio*",Tabla2[Universidad KPIs],'Utilización Convenios'!$C12,Tabla2[Año],'Utilización Convenios'!O$3,Tabla2[Nivel Nominación],"Undergraduate / Bachelor") -> 0 | Q12: =SUMIF($E$4:$P$4,Q$4,$E12:$P12) -> 4 | R12: =SUMIF($E$4:$P$4,R$4,$E12:$P12) -> 0
C13: EDHEC Business School | D13: France | E13: =COUNTIFS(Tabla1[Tipo de Movilidad],"Intercambio*",Tabla1[Universidad KPIs],'Utilización Convenios'!$C13,Tabla1[Año de Movilidad],'Utilización Convenios'!E$3,Tabla1[Nivel],"Pregrado") -> 0 | F13: =COUNTIFS(Tabla2[Tipo de Movilidad],"Intercambio*",Tabla2[Universidad KPIs],'Utilización Convenios'!$C13,Tabla2[Año],'Utilización Convenios'!E$3,Tabla2[Nivel Nominación],"Undergraduate / Bachelor") -> 1 | G13: =COUNTIFS(Tabla1[Tipo de Movilidad],"Intercambio*",Tabla1[Universidad KPIs],'Utilización Convenios'!$C13,Tabla1[Año de Movilidad],'Utilización Convenios'!G$3,Tabla1[Nivel],"Pregrado") -> 0 | H13: =COUNTIFS(Tabla2[Tipo de Movilidad],"Intercambio*",Tabla2[Universidad KPIs],'Utilización Convenios'!$C13,Tabla2[Año],'Utilización Convenios'!G$3,Tabla2[Nivel Nominación],"Undergraduate / Bachelor") -> 0 | I13: =COUNTIFS(Tabla1[Tipo de Movilidad],"Intercambio*",Tabla1[Universidad KPIs],'Utilización Convenios'!$C13,Tabla1[Año de Movilidad],'Utilización Convenios'!I$3,Tabla1[Nivel],"Pregrado") -> 3 | J13: =COUNTIFS(Tabla2[Tipo de Movilidad],"Intercambio*",Tabla2[Universidad KPIs],'Utilización Convenios'!$C13,Tabla2[Año],'Utilización Convenios'!I$3,Tabla2[Nivel Nominación],"Undergraduate / Bachelor") -> 0 | K13: =COUNTIFS(Tabla1[Tipo de Movilidad],"Intercambio*",Tabla1[Universidad KPIs],'Utilización Convenios'!$C13,Tabla1[Año de Movilidad],'Utilización Convenios'!K$3,Tabla1[Nivel],"Pregrado") -> 2 | L13: =COUNTIFS(Tabla2[Tipo de Movilidad],"Intercambio*",Tabla2[Universidad KPIs],'Utilización Convenios'!$C13,Tabla2[Año],'Utilización Convenios'!K$3,Tabla2[Nivel Nominación],"Undergraduate / Bachelor") -> 2 | M13: =COUNTIFS(Tabla1[Tipo de Movilidad],"Intercambio*",Tabla1[Universidad KPIs],'Utilización Convenios'!$C13,Tabla1[Año de Movilidad],'Utilización Convenios'!M$3,Tabla1[Nivel],"Pregrado") -> 2 | N13: =COUNTIFS(Tabla2[Tipo de Movilidad],"Intercambio*",Tabla2[Universidad KPIs],'Utilización Convenios'!$C13,Tabla2[Año],'Utilización Convenios'!M$3,Tabla2[Nivel Nominación],"Undergraduate / Bachelor") -> 0 | O13: =COUNTIFS(Tabla1[Tipo de Movilidad],"Intercambio*",Tabla1[Universidad KPIs],'Utilización Convenios'!$C13,Tabla1[Año de Movilidad],'Utilización Convenios'!O$3,Tabla1[Nivel],"Pregrado") -> 1 | P13: =COUNTIFS(Tabla2[Tipo de Movilidad],"Intercambio*",Tabla2[Universidad KPIs],'Utilización Convenios'!$C13,Tabla2[Año],'Utilización Convenios'!O$3,Tabla2[Nivel Nominación],"Undergraduate / Bachelor") -> 0 | Q13: =SUMIF($E$4:$P$4,Q$4,$E13:$P13) -> 8 | R13: =SUMIF($E$4:$P$4,R$4,$E13:$P13) -> 3
C14: EM Strasbourg | D14: France | E14: =COUNTIFS(Tabla1[Tipo de Movilidad],"Intercambio*",Tabla1[Universidad KPIs],'Utilización Convenios'!$C14,Tabla1[Año de Movilidad],'Utilización Convenios'!E$3,Tabla1[Nivel],"Pregrado") -> 0 | F14: =COUNTIFS(Tabla2[Tipo de Movilidad],"Intercambio*",Tabla2[Universidad KPIs],'Utilización Convenios'!$C14,Tabla2[Año],'Utilización Convenios'!E$3,Tabla2[Nivel Nominación],"Undergraduate / Bachelor") -> 1 | G14: =COUNTIFS(Tabla1[Tipo de Movilidad],"Intercambio*",Tabla1[Universidad KPIs],'Utilización Convenios'!$C14,Tabla1[Año de Movilidad],'Utilización Convenios'!G$3,Tabla1[Nivel],"Pregrado") -> 0 | H14: =COUNTIFS(Tabla2[Tipo de Movilidad],"Intercambio*",Tabla2[Universidad KPIs],'Utilización Convenios'!$C14,Tabla2[Año],'Utilización Convenios'!G$3,Tabla2[Nivel Nominación],"Undergraduate / Bachelor") -> 1 | I14: =COUNTIFS(Tabla1[Tipo de Movilidad],"Intercambio*",Tabla1[Universidad KPIs],'Utilización Convenios'!$C14,Tabla1[Año de Movilidad],'Utilización Convenios'!I$3,Tabla1[Nivel],"Pregrado") -> 0 | J14: =COUNTIFS(Tabla2[Tipo de Movilidad],"Intercambio*",Tabla2[Universidad KPIs],'Utilización Convenios'!$C14,Tabla2[Año],'Utilización Convenios'!I$3,Tabla2[Nivel Nominación],"Undergraduate / Bachelor") -> 1 | K14: =COUNTIFS(Tabla1[Tipo de Movilidad],"Intercambio*",Tabla1[Universidad KPIs],'Utilización Convenios'!$C14,Tabla1[Año de Movilidad],'Utilización Convenios'!K$3,Tabla1[Nivel],"Pregrado") -> 3 | L14: =COUNTIFS(Tabla2[Tipo de Movilidad],"Intercambio*",Tabla2[Universidad KPIs],'Utilización Convenios'!$C14,Tabla2[Año],'Utilización Convenios'!K$3,Tabla2[Nivel Nominación],"Undergraduate / Bachelor") -> 1 | M14: =COUNTIFS(Tabla1[Tipo de Movilidad],"Intercambio*",Tabla1[Universidad KPIs],'Utilización Convenios'!$C14,Tabla1[Año de Movilidad],'Utilización Convenios'!M$3,Tabla1[Nivel],"Pregrado") -> 2 | N14: =COUNTIFS(Tabla2[Tipo de Movilidad],"Intercambio*",Tabla2[Universidad KPIs],'Utilización Convenios'!$C14,Tabla2[Año],'Utilización Convenios'!M$3,Tabla2[Nivel Nominación],"Undergraduate / Bachelor") -> 1 | O14: =COUNTIFS(Tabla1[Tipo de Movilidad],"Intercambio*",Tabla1[Universidad KPIs],'Utilización Convenios'!$C14,Tabla1[Año de Movilidad],'Utilización Convenios'!O$3,Tabla1[Nivel],"Pregrado") -> 1 | P14: =COUNTIFS(Tabla2[Tipo de Movilidad],"Intercambio*",Tabla2[Universidad KPIs],'Utilización Convenios'!$C14,Tabla2[Año],'Utilización Convenios'!O$3,Tabla2[Nivel Nominación],"Undergraduate / Bachelor") -> 0 | Q14: =SUMIF($E$4:$P$4,Q$4,$E14:$P14) -> 6 | R14: =SUMIF($E$4:$P$4,R$4,$E14:$P14) -> 5
C15: ESADE | D15: Spain | E15: =COUNTIFS(Tabla1[Tipo de Movilidad],"Intercambio*",Tabla1[Universidad KPIs],'Utilización Convenios'!$C15,Tabla1[Año de Movilidad],'Utilización Convenios'!E$3,Tabla1[Nivel],"Pregrado") -> 2 | F15: =COUNTIFS(Tabla2[Tipo de Movilidad],"Intercambio*",Tabla2[Universidad KPIs],'Utilización Convenios'!$C15,Tabla2[Año],'Utilización Convenios'!E$3,Tabla2[Nivel Nominación],"Undergraduate / Bachelor") -> 0 | G15: =COUNTIFS(Tabla1[Tipo de Movilidad],"Intercambio*",Tabla1[Universidad KPIs],'Utilización Convenios'!$C15,Tabla1[Año de Movilidad],'Utilización Convenios'!G$3,Tabla1[Nivel],"Pregrado") -> 2 | H15: =COUNTIFS(Tabla2[Tipo de Movilidad],"Intercambio*",Tabla2[Universidad KPIs],'Utilización Convenios'!$C15,Tabla2[Año],'Utilización Convenios'!G$3,Tabla2[Nivel Nominación],"Undergraduate / Bachelor") -> 1 | I15: =COUNTIFS(Tabla1[Tipo de Movilidad],"Intercambio*",Tabla1[Universidad KPIs],'Utilización Convenios'!$C15,Tabla1[Año de Movilidad],'Utilización Convenios'!I$3,Tabla1[Nivel],"Pregrado") -> 6 | J15: =COUNTIFS(Tabla2[Tipo de Movilidad],"Intercambio*",Tabla2[Universidad KPIs],'Utilización Convenios'!$C15,Tabla2[Año],'Utilización Convenios'!I$3,Tabla2[Nivel Nominación],"Undergraduate / Bachelor") -> 1 | K15: =COUNTIFS(Tabla1[Tipo de Movilidad],"Intercambio*",Tabla1[Universidad KPIs],'Utilización Convenios'!$C15,Tabla1[Año de Movilidad],'Utilización Convenios'!K$3,Tabla1[Nivel],"Pregrado") -> 4 | L15: =COUNTIFS(Tabla2[Tipo de Movilidad],"Intercambio*",Tabla2[Universidad KPIs],'Utilización Convenios'!$C15,Tabla2[Año],'Utilización Convenios'!K$3,Tabla2[Nivel Nominación],"Undergraduate / Bachelor") -> 5 | M15: =COUNTIFS(Tabla1[Tipo de Movilidad],"Intercambio*",Tabla1[Universidad KPIs],'Utilización Convenios'!$C15,Tabla1[Año de Movilidad],'Utilización Convenios'!M$3,Tabla1[Nivel],"Pregrado") -> 2 | N15: =COUNTIFS(Tabla2[Tipo de Movilidad],"Intercambio*",Tabla2[Universidad KPIs],'Utilización Convenios'!$C15,Tabla2[Año],'Utilización Convenios'!M$3,Tabla2[Nivel Nominación],"Undergraduate / Bachelor") -> 2 | O15: =COUNTIFS(Tabla1[Tipo de Movilidad],"Intercambio*",Tabla1[Universidad KPIs],'Utilización Convenios'!$C15,Tabla1[Año de Movilidad],'Utilización Convenios'!O$3,Tabla1[Nivel],"Pregrado") -> 2 | P15: =COUNTIFS(Tabla2[Tipo de Movilidad],"Intercambio*",Tabla2[Universidad KPIs],'Utilización Convenios'!$C15,Tabla2[Año],'Utilización Convenios'!O$3,Tabla2[Nivel Nominación],"Undergraduate / Bachelor") -> 0 | Q15: =SUMIF($E$4:$P$4,Q$4,$E15:$P15) -> 18 | R15: =SUMIF($E$4:$P$4,R$4,$E15:$P15) -> 9
C16: ESC Rouen (NEOMA) | D16: France | E16: =COUNTIFS(Tabla1[Tipo de Movilidad],"Intercambio*",Tabla1[Universidad KPIs],'Utilización Convenios'!$C16,Tabla1[Año de Movilidad],'Utilización Convenios'!E$3,Tabla1[Nivel],"Pregrado") -> 1 | F16: =COUNTIFS(Tabla2[Tipo de Movilidad],"Intercambio*",Tabla2[Universidad KPIs],'Utilización Convenios'!$C16,Tabla2[Año],'Utilización Convenios'!E$3,Tabla2[Nivel Nominación],"Undergraduate / Bachelor") -> 0 | G16: =COUNTIFS(Tabla1[Tipo de Movilidad],"Intercambio*",Tabla1[Universidad KPIs],'Utilización Convenios'!$C16,Tabla1[Año de Movilidad],'Utilización Convenios'!G$3,Tabla1[Nivel],"Pregrado") -> 4 | H16: =COUNTIFS(Tabla2[Tipo de Movilidad],"Intercambio*",Tabla2[Universidad KPIs],'Utilización Convenios'!$C16,Tabla2[Año],'Utilización Convenios'!G$3,Tabla2[Nivel Nominación],"Undergraduate / Bachelor") -> 0 | I16: =COUNTIFS(Tabla1[Tipo de Movilidad],"Intercambio*",Tabla1[Universidad KPIs],'Utilización Convenios'!$C16,Tabla1[Año de Movilidad],'Utilización Convenios'!I$3,Tabla1[Nivel],"Pregrado") -> 6 | J16: =COUNTIFS(Tabla2[Tipo de Movilidad],"Intercambio*",Tabla2[Universidad KPIs],'Utilización Convenios'!$C16,Tabla2[Año],'Utilización Convenios'!I$3,Tabla2[Nivel Nominación],"Undergraduate / Bachelor") -> 0 | K16: =COUNTIFS(Tabla1[Tipo de Movilidad],"Intercambio*",Tabla1[Universidad KPIs],'Utilización Convenios'!$C16,Tabla1[Año de Movilidad],'Utilización Convenios'!K$3,Tabla1[Nivel],"Pregrado") -> 4 | L16: =COUNTIFS(Tabla2[Tipo de Movilidad],"Intercambio*",Tabla2[Universidad KPIs],'Utilización Convenios'!$C16,Tabla2[Año],'Utilización Convenios'!K$3,Tabla2[Nivel Nominación],"Undergraduate / Bachelor") -> 3 | M16: =COUNTIFS(Tabla1[Tipo de Movilidad],"Intercambio*",Tabla1[Universidad KPIs],'Utilización Convenios'!$C16,Tabla1[Año de Movilidad],'Utilización Convenios'!M$3,Tabla1[Nivel],"Pregrado") -> 2 | N16: =COUNTIFS(Tabla2[Tipo de Movilidad],"Intercambio*",Tabla2[Universidad KPIs],'Utilización Convenios'!$C16,Tabla2[Año],'Utilización Convenios'!M$3,Tabla2[Nivel Nominación],"Undergraduate / Bachelor") -> 0 | O16: =COUNTIFS(Tabla1[Tipo de Movilidad],"Intercambio*",Tabla1[Universidad KPIs],'Utilización Convenios'!$C16,Tabla1[Año de Movilidad],'Utilización Convenios'!O$3,Tabla1[Nivel],"Pregrado") -> 2 | P16: =COUNTIFS(Tabla2[Tipo de Movilidad],"Intercambio*",Tabla2[Universidad KPIs],'Utilización Convenios'!$C16,Tabla2[Año],'Utilización Convenios'!O$3,Tabla2[Nivel Nominación],"Undergraduate / Bachelor") -> 1 | Q16: =SUMIF($E$4:$P$4,Q$4,$E16:$P16) -> 19 | R16: =SUMIF($E$4:$P$4,R$4,$E16:$P16) -> 4
C17: ESCP | D17: France | E17: =COUNTIFS(Tabla1[Tipo de Movilidad],"Intercambio*",Tabla1[Universidad KPIs],'Utilización Convenios'!$C17,Tabla1[Año de Movilidad],'Utilización Convenios'!E$3,Tabla1[Nivel],"Pregrado") -> 1 | F17: =COUNTIFS(Tabla2[Tipo de Movilidad],"Intercambio*",Tabla2[Universidad KPIs],'Utilización Convenios'!$C17,Tabla2[Año],'Utilización Convenios'!E$3,Tabla2[Nivel Nominación],"Undergraduate / Bachelor") -> 0 | G17: =COUNTIFS(Tabla1[Tipo de Movilidad],"Intercambio*",Tabla1[Universidad KPIs],'Utilización Convenios'!$C17,Tabla1[Año de Movilidad],'Utilización Convenios'!G$3,Tabla1[Nivel],"Pregrado") -> 3 | H17: =COUNTIFS(Tabla2[Tipo de Movilidad],"Intercambio*",Tabla2[Universidad KPIs],'Utilización Convenios'!$C17,Tabla2[Año],'Utilización Convenios'!G$3,Tabla2[Nivel Nominación],"Undergraduate / Bachelor") -> 0 | I17: =COUNTIFS(Tabla1[Tipo de Movilidad],"Intercambio*",Tabla1[Universidad KPIs],'Utilización Convenios'!$C17,Tabla1[Año de Movilidad],'Utilización Convenios'!I$3,Tabla1[Nivel],"Pregrado") -> 0 | J17: =COUNTIFS(Tabla2[Tipo de Movilidad],"Intercambio*",Tabla2[Universidad KPIs],'Utilización Convenios'!$C17,Tabla2[Año],'Utilización Convenios'!I$3,Tabla2[Nivel Nominación],"Undergraduate / Bachelor") -> 0 | K17: =COUNTIFS(Tabla1[Tipo de Movilidad],"Intercambio*",Tabla1[Universidad KPIs],'Utilización Convenios'!$C17,Tabla1[Año de Movilidad],'Utilización Convenios'!K$3,Tabla1[Nivel],"Pregrado") -> 4 | L17: =COUNTIFS(Tabla2[Tipo de Movilidad],"Intercambio*",Tabla2[Universidad KPIs],'Utilización Convenios'!$C17,Tabla2[Año],'Utilización Convenios'!K$3,Tabla2[Nivel Nominación],"Undergraduate / Bachelor") -> 0 | M17: =COUNTIFS(Tabla1[Tipo de Movilidad],"Intercambio*",Tabla1[Universidad KPIs],'Utilización Convenios'!$C17,Tabla1[Año de Movilidad],'Utilización Convenios'!M$3,Tabla1[Nivel],"Pregrado") -> 3 | N17: =COUNTIFS(Tabla2[Tipo de Movilidad],"Intercambio*",Tabla2[Universidad KPIs],'Utilización Convenios'!$C17,Tabla2[Año],'Utilización Convenios'!M$3,Tabla2[Nivel Nominación],"Undergraduate / Bachelor") -> 1 | O17: =COUNTIFS(Tabla1[Tipo de Movilidad],"Intercambio*",Tabla1[Universidad KPIs],'Utilización Convenios'!$C17,Tabla1[Año de Movilidad],'Utilización Convenios'!O$3,Tabla1[Nivel],"Pregrado") -> 1 | P17: =COUNTIFS(Tabla2[Tipo de Movilidad],"Intercambio*",Tabla2[Universidad KPIs],'Utilización Convenios'!$C17,Tabla2[Año],'Utilización Convenios'!O$3,Tabla2[Nivel Nominación],"Undergraduate / Bachelor") -> 0 | Q17: =SUMIF($E$4:$P$4,Q$4,$E17:$P17) -> 12 | R17: =SUMIF($E$4:$P$4,R$4,$E17:$P17) -> 1
... C63: Warsaw School of Economics | D63: Warsaw | E63: =COUNTIFS(Tabla1[Tipo de Movilidad],"Intercambio*",Tabla1[Universidad KPIs],'Utilización Convenios'!$C63,Tabla1[Año de Movilidad],'Utilización Convenios'!E$3,Tabla1[Nivel],"Pregrado") -> 0 | F63: =COUNTIFS(Tabla2[Tipo de Movilidad],"Intercambio*",Tabla2[Universidad KPIs],'Utilización Convenios'!$C63,Tabla2[Año],'Utilización Convenios'!E$3,Tabla2[Nivel Nominación],"Undergraduate / Bachelor") -> 0 | G63: =COUNTIFS(Tabla1[Tipo de Movilidad],"Intercambio*",Tabla1[Universidad KPIs],'Utilización Convenios'!$C63,Tabla1[Año de Movilidad],'Utilización Convenios'!G$3,Tabla1[Nivel],"Pregrado") -> 0 | H63: =COUNTIFS(Tabla2[Tipo de Movilidad],"Intercambio*",Tabla2[Universidad KPIs],'Utilización Convenios'!$C63,Tabla2[Año],'Utilización Convenios'!G$3,Tabla2[Nivel Nominación],"Undergraduate / Bachelor") -> 0 | I63: =COUNTIFS(Tabla1[Tipo de Movilidad],"Intercambio*",Tabla1[Universidad KPIs],'Utilización Convenios'!$C63,Tabla1[Año de Movilidad],'Utilización Convenios'!I$3,Tabla1[Nivel],"Pregrado") -> 0 | J63: =COUNTIFS(Tabla2[Tipo de Movilidad],"Intercambio*",Tabla2[Universidad KPIs],'Utilización Convenios'!$C63,Tabla2[Año],'Utilización Convenios'!I$3,Tabla2[Nivel Nominación],"Undergraduate / Bachelor") -> 0 | K63: =COUNTIFS(Tabla1[Tipo de Movilidad],"Intercambio*",Tabla1[Universidad KPIs],'Utilización Convenios'!$C63,Tabla1[Año de Movilidad],'Utilización Convenios'!K$3,Tabla1[Nivel],"Pregrado") -> 0 | L63: =COUNTIFS(Tabla2[Tipo de Movilidad],"Intercambio*",Tabla2[Universidad KPIs],'Utilización Convenios'!$C63,Tabla2[Año],'Utilización Convenios'!K$3,Tabla2[Nivel Nominación],"Undergraduate / Bachelor") -> 0 | M63: =COUNTIFS(Tabla1[Tipo de Movilidad],"Intercambio*",Tabla1[Universidad KPIs],'Utilización Convenios'!$C63,Tabla1[Año de Movilidad],'Utilización Convenios'!M$3,Tabla1[Nivel],"Pregrado") -> 0 | N63: =COUNTIFS(Tabla2[Tipo de Movilidad],"Intercambio*",Tabla2[Universidad KPIs],'Utilización Convenios'!$C63,Tabla2[Año],'Utilización Convenios'!M$3,Tabla2[Nivel Nominación],"Undergraduate / Bachelor") -> 0 | O63: =COUNTIFS(Tabla1[Tipo de Movilidad],"Intercambio*",Tabla1[Universidad KPIs],'Utilización Convenios'!$C63,Tabla1[Año de Movilidad],'Utilización Convenios'!O$3,Tabla1[Nivel],"Pregrado") -> 0 | P63: =COUNTIFS(Tabla2[Tipo de Movilidad],"Intercambio*",Tabla2[Universidad KPIs],'Utilización Convenios'!$C63,Tabla2[Año],'Utilización Convenios'!O$3,Tabla2[Nivel Nominación],"Undergraduate / Bachelor") -> 0 | Q63: =SUMIF($E$4:$P$4,Q$4,$E63:$P63) -> 0 | R63: =SUMIF($E$4:$P$4,R$4,$E63:$P63) -> 0
B64: C O N V E N I O S G E N E E R A L E S | C64: American University of Central Asia | D64: Kyrgyzstan | E64: =COUNTIFS(Tabla1[Tipo de Movilidad],"Intercambio*",Tabla1[Universidad KPIs],'Utilización Convenios'!$C64,Tabla1[Año de Movilidad],'Utilización Convenios'!E$3,Tabla1[Nivel],"Pregrado") -> 0 | F64: =COUNTIFS(Tabla2[Tipo de Movilidad],"Intercambio*",Tabla2[Universidad KPIs],'Utilización Convenios'!$C64,Tabla2[Año],'Utilización Convenios'!E$3,Tabla2[Nivel Nominación],"Undergraduate / Bachelor") -> 0 | G64: =COUNTIFS(Tabla1[Tipo de Movilidad],"Intercambio*",Tabla1[Universidad KPIs],'Utilización Convenios'!$C64,Tabla1[Año de Movilidad],'Utilización Convenios'!G$3,Tabla1[Nivel],"Pregrado") -> 0 | H64: =COUNTIFS(Tabla2[Tipo de Movilidad],"Intercambio*",Tabla2[Universidad KPIs],'Utilización Convenios'!$C64,Tabla2[Año],'Utilización Convenios'!G$3,Tabla2[Nivel Nominación],"Undergraduate / Bachelor") -> 0 | I64: =COUNTIFS(Tabla1[Tipo de Movilidad],"Intercambio*",Tabla1[Universidad KPIs],'Utilización Convenios'!$C64,Tabla1[Año de Movilidad],'Utilización Convenios'!I$3,Tabla1[Nivel],"Pregrado") -> 0 | J64: =COUNTIFS(Tabla2[Tipo de Movilidad],"Intercambio*",Tabla2[Universidad KPIs],'Utilización Convenios'!$C64,Tabla2[Año],'Utilización Convenios'!I$3,Tabla2[Nivel Nominación],"Undergraduate / Bachelor") -> 0 | K64: =COUNTIFS(Tabla1[Tipo de Movilidad],"Intercambio*",Tabla1[Universidad KPIs],'Utilización Convenios'!$C64,Tabla1[Año de Movilidad],'Utilización Convenios'!K$3,Tabla1[Nivel],"Pregrado") -> 1 | L64: =COUNTIFS(Tabla2[Tipo de Movilidad],"Intercambio*",Tabla2[Universidad KPIs],'Utilización Convenios'!$C64,Tabla2[Año],'Utilización Convenios'!K$3,Tabla2[Nivel Nominación],"Undergraduate / Bachelor") -> 2 | M64: =COUNTIFS(Tabla1[Tipo de Movilidad],"Intercambio*",Tabla1[Universidad KPIs],'Utilización Convenios'!$C64,Tabla1[Año de Movilidad],'Utilización Convenios'!M$3,Tabla1[Nivel],"Pregrado") -> 0 | N64: =COUNTIFS(Tabla2[Tipo de Movilidad],"Intercambio*",Tabla2[Universidad KPIs],'Utilización Convenios'!$C64,Tabla2[Año],'Utilización Convenios'!M$3,Tabla2[Nivel Nominación],"Undergraduate / Bachelor") -> 2 | O64: =COUNTIFS(Tabla1[Tipo de Movilidad],"Intercambio*",Tabla1[Universidad KPIs],'Utilización Convenios'!$C64,Tabla1[Año de Movilidad],'Utilización Convenios'!O$3,Tabla1[Nivel],"Pregrado") -> 0 | P64: =COUNTIFS(Tabla2[Tipo de Movilidad],"Intercambio*",Tabla2[Universidad KPIs],'Utilización Convenios'!$C64,Tabla2[Año],'Utilización Convenios'!O$3,Tabla2[Nivel Nominación],"Undergraduate / Bachelor") -> 0 | Q64: =SUMIF($E$4:$P$4,Q$4,$E64:$P64) -> 1 | R64: =SUMIF($E$4:$P$4,R$4,$E64:$P64) -> 4
C65: Amherst College | D65: United States | E65: =COUNTIFS(Tabla1[Tipo de Movilidad],"Intercambio*",Tabla1[Universidad KPIs],'Utilización Convenios'!$C65,Tabla1[Año de Movilidad],'Utilización Convenios'!E$3,Tabla1[Nivel],"Pregrado") -> 0 | F65: =COUNTIFS(Tabla2[Tipo de Movilidad],"Intercambio*",Tabla2[Universidad KPIs],'Utilización Convenios'!$C65,Tabla2[Año],'Utilización Convenios'!E$3,Tabla2[Nivel Nominación],"Undergraduate / Bachelor") -> 0 | G65: =COUNTIFS(Tabla1[Tipo de Movilidad],"Intercambio*",Tabla1[Universidad KPIs],'Utilización Convenios'!$C65,Tabla1[Año de Movilidad],'Utilización Convenios'!G$3,Tabla1[Nivel],"Pregrado") -> 0 | H65: =COUNTIFS(Tabla2[Tipo de Movilidad],"Intercambio*",Tabla2[Universidad KPIs],'Utilización Convenios'!$C65,Tabla2[Año],'Utilización Convenios'!G$3,Tabla2[Nivel Nominación],"Undergraduate / Bachelor") -> 0 | I65: =COUNTIFS(Tabla1[Tipo de Movilidad],"Intercambio*",Tabla1[Universidad KPIs],'Utilización Convenios'!$C65,Tabla1[Año de Movilidad],'Utilización Convenios'!I$3,Tabla1[Nivel],"Pregrado") -> 0 | J65: =COUNTIFS(Tabla2[Tipo de Movilidad],"Intercambio*",Tabla2[Universidad KPIs],'Utilización Convenios'!$C65,Tabla2[Año],'Utilización Convenios'!I$3,Tabla2[Nivel Nominación],"Undergraduate / Bachelor") -> 0 | K65: =COUNTIFS(Tabla1[Tipo de Movilidad],"Intercambio*",Tabla1[Universidad KPIs],'Utilización Convenios'!$C65,Tabla1[Año de Movilidad],'Utilización Convenios'!K$3,Tabla1[Nivel],"Pregrado") -> 0 | L65: =COUNTIFS(Tabla2[Tipo de Movilidad],"Intercambio*",Tabla2[Universidad KPIs],'Utilización Convenios'!$C65,Tabla2[Año],'Utilización Convenios'!K$3,Tabla2[Nivel Nominación],"Undergraduate / Bachelor") -> 0 | M65: =COUNTIFS(Tabla1[Tipo de Movilidad],"Intercambio*",Tabla1[Universidad KPIs],'Utilización Convenios'!$C65,Tabla1[Año de Movilidad],'Utilización Convenios'!M$3,Tabla1[Nivel],"Pregrado") -> 1 | N65: =COUNTIFS(Tabla2[Tipo de Movilidad],"Intercambio*",Tabla2[Universidad KPIs],'Utilización Convenios'!$C65,Tabla2[Año],'Utilización Convenios'!M$3,Tabla2[Nivel Nominación],"Undergraduate / Bachelor") -> 0 | O65: =COUNTIFS(Tabla1[Tipo de Movilidad],"Intercambio*",Tabla1[Universidad KPIs],'Utilización Convenios'!$C65,Tabla1[Año de Movilidad],'Utilización Convenios'!O$3,Tabla1[Nivel],"Pregrado") -> 1 | P65: =COUNTIFS(Tabla2[Tipo de Movilidad],"Intercambio*",Tabla2[Universidad KPIs],'Utilización Convenios'!$C65,Tabla2[Año],'Utilización Convenios'!O$3,Tabla2[Nivel Nominación],"Undergraduate / Bachelor") -> 0 | Q65: =SUMIF($E$4:$P$4,Q$4,$E65:$P65) -> 2 | R65: =SUMIF($E$4:$P$4,R$4,$E65:$P65) -> 0
C66: Curtin University | D66: Australia | E66: =COUNTIFS(Tabla1[Tipo de Movilidad],"Intercambio*",Tabla1[Universidad KPIs],'Utilización Convenios'!$C66,Tabla1[Año de Movilidad],'Utilización Convenios'!E$3,Tabla1[Nivel],"Pregrado") -> 0 | F66: =COUNTIFS(Tabla2[Tipo de Movilidad],"Intercambio*",Tabla2[Universidad KPIs],'Utilización Convenios'!$C66,Tabla2[Año],'Utilización Convenios'!E$3,Tabla2[Nivel Nominación],"Undergraduate / Bachelor") -> 0 | G66: =COUNTIFS(Tabla1[Tipo de Movilidad],"Intercambio*",Tabla1[Universidad KPIs],'Utilización Convenios'!$C66,Tabla1[Año de Movilidad],'Utilización Convenios'!G$3,Tabla1[Nivel],"Pregrado") -> 0 | H66: =COUNTIFS(Tabla2[Tipo de Movilidad],"Intercambio*",Tabla2[Universidad KPIs],'Utilización Convenios'!$C66,Tabla2[Año],'Utilización Convenios'!G$3,Tabla2[Nivel Nominación],"Undergraduate / Bachelor") -> 0 | I66: =COUNTIFS(Tabla1[Tipo de Movilidad],"Intercambio*",Tabla1[Universidad KPIs],'Utilización Convenios'!$C66,Tabla1[Año de Movilidad],'Utilización Convenios'!I$3,Tabla1[Nivel],"Pregrado") -> 0 | J66: =COUNTIFS(Tabla2[Tipo de Movilidad],"Intercambio*",Tabla2[Universidad KPIs],'Utilización Convenios'!$C66,Tabla2[Año],'Utilización Convenios'!I$3,Tabla2[Nivel Nominación],"Undergraduate / Bachelor") -> 0 | K66: =COUNTIFS(Tabla1[Tipo de Movilidad],"Intercambio*",Tabla1[Universidad KPIs],'Utilización Convenios'!$C66,Tabla1[Año de Movilidad],'Utilización Convenios'!K$3,Tabla1[Nivel],"Pregrado") -> 1 | L66: =COUNTIFS(Tabla2[Tipo de Movilidad],"Intercambio*",Tabla2[Universidad KPIs],'Utilización Convenios'!$C66,Tabla2[Año],'Utilización Convenios'!K$3,Tabla2[Nivel Nominación],"Undergraduate / Bachelor") -> 0 | M66: =COUNTIFS(Tabla1[Tipo de Movilidad],"Intercambio*",Tabla1[Universidad KPIs],'Utilización Convenios'!$C66,Tabla1[Año de Movilidad],'Utilización Convenios'!M$3,Tabla1[Nivel],"Pregrado") -> 0 | N66: =COUNTIFS(Tabla2[Tipo de Movilidad],"Intercambio*",Tabla2[Universidad KPIs],'Utilización Convenios'!$C66,Tabla2[Año],'Utilización Convenios'!M$3,Tabla2[Nivel Nominación],"Undergraduate / Bachelor") -> 0 | O66: =COUNTIFS(Tabla1[Tipo de Movilidad],"Intercambio*",Tabla1[Universidad KPIs],'Utilización Convenios'!$C66,Tabla1[Año de Movilidad],'Utilización Convenios'!O$3,Tabla1[Nivel],"Pregrado") -> 0 | P66: =COUNTIFS(Tabla2[Tipo de Movilidad],"Intercambio*",Tabla2[Universidad KPIs],'Utilización Convenios'!$C66,Tabla2[Año],'Utilización Convenios'!O$3,Tabla2[Nivel Nominación],"Undergraduate / Bachelor") -> 0 | Q66: =SUMIF($E$4:$P$4,Q$4,$E66:$P66) -> 1 | R66: =SUMIF($E$4:$P$4,R$4,$E66:$P66) -> 0
C67: CY Cergy Paris Université | D67: France | E67: =COUNTIFS(Tabla1[Tipo de Movilidad],"Intercambio*",Tabla1[Universidad KPIs],'Utilización Convenios'!$C67,Tabla1[Año de Movilidad],'Utilización Convenios'!E$3,Tabla1[Nivel],"Pregrado") -> 0 | F67: =COUNTIFS(Tabla2[Tipo de Movilidad],"Intercambio*",Tabla2[Universidad KPIs],'Utilización Convenios'!$C67,Tabla2[Año],'Utilización Convenios'!E$3,Tabla2[Nivel Nominación],"Undergraduate / Bachelor") -> 0 | G67: =COUNTIFS(Tabla1[Tipo de Movilidad],"Intercambio*",Tabla1[Universidad KPIs],'Utilización Convenios'!$C67,Tabla1[Año de Movilidad],'Utilización Convenios'!G$3,Tabla1[Nivel],"Pregrado") -> 0 | H67: =COUNTIFS(Tabla2[Tipo de Movilidad],"Intercambio*",Tabla2[Universidad KPIs],'Utilización Convenios'!$C67,Tabla2[Año],'Utilización Convenios'!G$3,Tabla2[Nivel Nominación],"Undergraduate / Bachelor") -> 2 | I67: =COUNTIFS(Tabla1[Tipo de Movilidad],"Intercambio*",Tabla1[Universidad KPIs],'Utilización Convenios'!$C67,Tabla1[Año de Movilidad],'Utilización Convenios'!I$3,Tabla1[Nivel],"Pregrado") -> 0 | J67: =COUNTIFS(Tabla2[Tipo de Movilidad],"Intercambio*",Tabla2[Universidad KPIs],'Utilización Convenios'!$C67,Tabla2[Año],'Utilización Convenios'!I$3,Tabla2[Nivel Nominación],"Undergraduate / Bachelor") -> 0 | K67: =COUNTIFS(Tabla1[Tipo de Movilidad],"Intercambio*",Tabla1[Universidad KPIs],'Utilización Convenios'!$C67,Tabla1[Año de Movilidad],'Utilización Convenios'!K$3,Tabla1[Nivel],"Pregrado") -> 0 | L67: =COUNTIFS(Tabla2[Tipo de Movilidad],"Intercambio*",Tabla2[Universidad KPIs],'Utilización Convenios'!$C67,Tabla2[Año],'Utilización Convenios'!K$3,Tabla2[Nivel Nominación],"Undergraduate / Bachelor") -> 0 | M67: =COUNTIFS(Tabla1[Tipo de Movilidad],"Intercambio*",Tabla1[Universidad KPIs],'Utilización Convenios'!$C67,Tabla1[Año de Movilidad],'Utilización Convenios'!M$3,Tabla1[Nivel],"Pregrado") -> 0 | N67: =COUNTIFS(Tabla2[Tipo de Movilidad],"Intercambio*",Tabla2[Universidad KPIs],'Utilización Convenios'!$C67,Tabla2[Año],'Utilización Convenios'!M$3,Tabla2[Nivel Nominación],"Undergraduate / Bachelor") -> 0 | O67: =COUNTIFS(Tabla1[Tipo de Movilidad],"Intercambio*",Tabla1[Universidad KPIs],'Utilización Convenios'!$C67,Tabla1[Año de Movilidad],'Utilización Convenios'!O$3,Tabla1[Nivel],"Pregrado") -> 0 | P67: =COUNTIFS(Tabla2[Tipo de Movilidad],"Intercambio*",Tabla2[Universidad KPIs],'Utilización Convenios'!$C67,Tabla2[Año],'Utilización Convenios'!O$3,Tabla2[Nivel Nominación],"Undergraduate / Bachelor") -> 0 | Q67: =SUMIF($E$4:$P$4,Q$4,$E67:$P67) -> 0 | R67: =SUMIF($E$4:$P$4,R$4,$E67:$P67) -> 2
C68: FHNW Fachhochschule Nordwestschweiz | D68: Switzerland | E68: =COUNTIFS(Tabla1[Tipo de Movilidad],"Intercambio*",Tabla1[Universidad KPIs],'Utilización Convenios'!$C68,Tabla1[Año de Movilidad],'Utilización Convenios'!E$3,Tabla1[Nivel],"Pregrado") -> 0 | F68: =COUNTIFS(Tabla2[Tipo de Movilidad],"Intercambio*",Tabla2[Universidad KPIs],'Utilización Convenios'!$C68,Tabla2[Año],'Utilización Convenios'!E$3,Tabla2[Nivel Nominación],"Undergraduate / Bachelor") -> 1 | G68: =COUNTIFS(Tabla1[Tipo de Movilidad],"Intercambio*",Tabla1[Universidad KPIs],'Utilización Convenios'!$C68,Tabla1[Año de Movilidad],'Utilización Convenios'!G$3,Tabla1[Nivel],"Pregrado") -> 0 | H68: =COUNTIFS(Tabla2[Tipo de Movilidad],"Intercambio*",Tabla2[Universidad KPIs],'Utilización Convenios'!$C68,Tabla2[Año],'Utilización Convenios'!G$3,Tabla2[Nivel Nominación],"Undergraduate / Bachelor") -> 1 | I68: =COUNTIFS(Tabla1[Tipo de Movilidad],"Intercambio*",Tabla1[Universidad KPIs],'Utilización Convenios'!$C68,Tabla1[Año de Movilidad],'Utilización Convenios'!I$3,Tabla1[Nivel],"Pregrado") -> 0 | J68: =COUNTIFS(Tabla2[Tipo de Movilidad],"Intercambio*",Tabla2[Universidad KPIs],'Utilización Convenios'!$C68,Tabla2[Año],'Utilización Convenios'!I$3,Tabla2[Nivel Nominación],"Undergraduate / Bachelor") -> 0 | K68: =COUNTIFS(Tabla1[Tipo de Movilidad],"Intercambio*",Tabla1[Universidad KPIs],'Utilización Convenios'!$C68,Tabla1[Año de Movilidad],'Utilización Convenios'!K$3,Tabla1[Nivel],"Pregrado") -> 0 | L68: =COUNTIFS(Tabla2[Tipo de Movilidad],"Intercambio*",Tabla2[Universidad KPIs],'Utilización Convenios'!$C68,Tabla2[Año],'Utilización Convenios'!K$3,Tabla2[Nivel Nominación],"Undergraduate / Bachelor") -> 0 | M68: =COUNTIFS(Tabla1[Tipo de Movilidad],"Intercambio*",Tabla1[Universidad KPIs],'Utilización Convenios'!$C68,Tabla1[Año de Movilidad],'Utilización Convenios'!M$3,Tabla1[Nivel],"Pregrado") -> 0 | N68: =COUNTIFS(Tabla2[Tipo de Movilidad],"Intercambio*",Tabla2[Universidad KPIs],'Utilización Convenios'!$C68,Tabla2[Año],'Utilización Convenios'!M$3,Tabla2[Nivel Nominación],"Undergraduate / Bachelor") -> 1 | O68: =COUNTIFS(Tabla1[Tipo de Movilidad],"Intercambio*",Tabla1[Universidad KPIs],'Utilización Convenios'!$C68,Tabla1[Año de Movilidad],'Utilización Convenios'!O$3,Tabla1[Nivel],"Pregrado") -> 0 | P68: =COUNTIFS(Tabla2[Tipo de Movilidad],"Intercambio*",Tabla2[Universidad KPIs],'Utilización Convenios'!$C68,Tabla2[Año],'Utilización Convenios'!O$3,Tabla2[Nivel Nominación],"Undergraduate / Bachelor") -> 0 | Q68: =SUMIF($E$4:$P$4,Q$4,$E68:$P68) -> 0 | R68: =SUMIF($E$4:$P$4,R$4,$E68:$P68) -> 3
C69: Institut d’Etudes Politiques de Paris | D69: France | E69: =COUNTIFS(Tabla1[Tipo de Movilidad],"Intercambio*",Tabla1[Universidad KPIs],'Utilización Convenios'!$C69,Tabla1[Año de Movilidad],'Utilización Convenios'!E$3,Tabla1[Nivel],"Pregrado") -> 0 | F69: =COUNTIFS(Tabla2[Tipo de Movilidad],"Intercambio*",Tabla2[Universidad KPIs],'Utilización Convenios'!$C69,Tabla2[Año],'Utilización Convenios'!E$3,Tabla2[Nivel Nominación],"Undergraduate / Bachelor") -> 0 | G69: =COUNTIFS(Tabla1[Tipo de Movilidad],"Intercambio*",Tabla1[Universidad KPIs],'Utilización Convenios'!$C69,Tabla1[Año de Movilidad],'Utilización Convenios'!G$3,Tabla1[Nivel],"Pregrado") -> 0 | H69: =COUNTIFS(Tabla2[Tipo de Movilidad],"Intercambio*",Tabla2[Universidad KPIs],'Utilización Convenios'!$C69,Tabla2[Año],'Utilización Convenios'!G$3,Tabla2[Nivel Nominación],"Undergraduate / Bachelor") -> 0 | I69: =COUNTIFS(Tabla1[Tipo de Movilidad],"Intercambio*",Tabla1[Universidad KPIs],'Utilización Convenios'!$C69,Tabla1[Año de Movilidad],'Utilización Convenios'!I$3,Tabla1[Nivel],"Pregrado") -> 0 | J69: =COUNTIFS(Tabla2[Tipo de Movilidad],"Intercambio*",Tabla2[Universidad KPIs],'Utilización Convenios'!$C69,Tabla2[Año],'Utilización Convenios'!I$3,Tabla2[Nivel Nominación],"Undergraduate / Bachelor") -> 1 | K69: =COUNTIFS(Tabla1[Tipo de Movilidad],"Intercambio*",Tabla1[Universidad KPIs],'Utilización Convenios'!$C69,Tabla1[Año de Movilidad],'Utilización Convenios'!K$3,Tabla1[Nivel],"Pregrado") -> 0 | L69: =COUNTIFS(Tabla2[Tipo de Movilidad],"Intercambio*",Tabla2[Universidad KPIs],'Utilización Convenios'!$C69,Tabla2[Año],'Utilización Convenios'!K$3,Tabla2[Nivel Nominación],"Undergraduate / Bachelor") -> 0 | M69: =COUNTIFS(Tabla1[Tipo de Movilidad],"Intercambio*",Tabla1[Universidad KPIs],'Utilización Convenios'!$C69,Tabla1[Año de Movilidad],'Utilización Convenios'!M$3,Tabla1[Nivel],"Pregrado") -> 0 | N69: =COUNTIFS(Tabla2[Tipo de Movilidad],"Intercambio*",Tabla2[Universidad KPIs],'Utilización Convenios'!$C69,Tabla2[Año],'Utilización Convenios'!M$3,Tabla2[Nivel Nominación],"Undergraduate / Bachelor") -> 0 | O69: =COUNTIFS(Tabla1[Tipo de Movilidad],"Intercambio*",Tabla1[Universidad KPIs],'Utilización Convenios'!$C69,Tabla1[Año de Movilidad],'Utilización Convenios'!O$3,Tabla1[Nivel],"Pregrado") -> 0 | P69: =COUNTIFS(Tabla2[Tipo de Movilidad],"Intercambio*",Tabla2[Universidad KPIs],'Utilización Convenios'!$C69,Tabla2[Año],'Utilización Convenios'!O$3,Tabla2[Nivel Nominación],"Undergraduate / Bachelor") -> 0 | Q69: =SUMIF($E$4:$P$4,Q$4,$E69:$P69) -> 0 | R69: =SUMIF($E$4:$P$4,R$4,$E69:$P69) -> 1
C70: Johannes Gutemberg - Universität Mainz | D70: Germany | E70: =COUNTIFS(Tabla1[Tipo de Movilidad],"Intercambio*",Tabla1[Universidad KPIs],'Utilización Convenios'!$C70,Tabla1[Año de Movilidad],'Utilización Convenios'!E$3,Tabla1[Nivel],"Pregrado") -> 0 | F70: =COUNTIFS(Tabla2[Tipo de Movilidad],"Intercambio*",Tabla2[Universidad KPIs],'Utilización Convenios'!$C70,Tabla2[Año],'Utilización Convenios'!E$3,Tabla2[Nivel Nominación],"Undergraduate / Bachelor") -> 0 | G70: =COUNTIFS(Tabla1[Tipo de Movilidad],"Intercambio*",Tabla1[Universidad KPIs],'Utilización Convenios'!$C70,Tabla1[Año de Movilidad],'Utilización Convenios'!G$3,Tabla1[Nivel],"Pregrado") -> 0 | H70: =COUNTIFS(Tabla2[Tipo de Movilidad],"Intercambio*",Tabla2[Universidad KPIs],'Utilización Convenios'!$C70,Tabla2[Año],'Utilización Convenios'!G$3,Tabla2[Nivel Nominación],"Undergraduate / Bachelor") -> 0 | I70: =COUNTIFS(Tabla1[Tipo de Movilidad],"Intercambio*",Tabla1[Universidad KPIs],'Utilización Convenios'!$C70,Tabla1[Año de Movilidad],'Utilización Convenios'!I$3,Tabla1[Nivel],"Pregrado") -> 1 | J70: =COUNTIFS(Tabla2[Tipo de Movilidad],"Intercambio*",Tabla2[Universidad KPIs],'Utilización Convenios'!$C70,Tabla2[Año],'Utilización Convenios'!I$3,Tabla2[Nivel Nominación],"Undergraduate / Bachelor") -> 0 | K70: =COUNTIFS(Tabla1[Tipo de Movilidad],"Intercambio*",Tabla1[Universidad KPIs],'Utilización Convenios'!$C70,Tabla1[Año de Movilidad],'Utilización Convenios'!K$3,Tabla1[Nivel],"Pregrado") -> 0 | L70: =COUNTIFS(Tabla2[Tipo de Movilidad],"Intercambio*",Tabla2[Universidad KPIs],'Utilización Convenios'!$C70,Tabla2[Año],'Utilización Convenios'!K$3,Tabla2[Nivel Nominación],"Undergraduate / Bachelor") -> 0 | M70: =COUNTIFS(Tabla1[Tipo de Movilidad],"Intercambio*",Tabla1[Universidad KPIs],'Utilización Convenios'!$C70,Tabla1[Año de Movilidad],'Utilización Convenios'!M$3,Tabla1[Nivel],"Pregrado") -> 0 | N70: =COUNTIFS(Tabla2[Tipo de Movilidad],"Intercambio*",Tabla2[Universidad KPIs],'Utilización Convenios'!$C70,Tabla2[Año],'Utilización Convenios'!M$3,Tabla2[Nivel Nominación],"Undergraduate / Bachelor") -> 0 | O70: =COUNTIFS(Tabla1[Tipo de Movilidad],"Intercambio*",Tabla1[Universidad KPIs],'Utilización Convenios'!$C70,Tabla1[Año de Movilidad],'Utilización Convenios'!O$3,Tabla1[Nivel],"Pregrado") -> 0 | P70: =COUNTIFS(Tabla2[Tipo de Movilidad],"Intercambio*",Tabla2[Universidad KPIs],'Utilización Convenios'!$C70,Tabla2[Año],'Utilización Convenios'!O$3,Tabla2[Nivel Nominación],"Undergraduate / Bachelor") -> 0 | Q70: =SUMIF($E$4:$P$4,Q$4,$E70:$P70) -> 1 | R70: =SUMIF($E$4:$P$4,R$4,$E70:$P70) -> 0
C71: Northumbria University, Newcastle | D71: United Kingdom | E71: =COUNTIFS(Tabla1[Tipo de Movilidad],"Intercambio*",Tabla1[Universidad KPIs],'Utilización Convenios'!$C71,Tabla1[Año de Movilidad],'Utilización Convenios'!E$3,Tabla1[Nivel],"Pregrado") -> 0 | F71: =COUNTIFS(Tabla2[Tipo de Movilidad],"Intercambio*",Tabla2[Universidad KPIs],'Utilización Convenios'!$C71,Tabla2[Año],'Utilización Convenios'!E$3,Tabla2[Nivel Nominación],"Undergraduate / Bachelor") -> 1 | G71: =COUNTIFS(Tabla1[Tipo de Movilidad],"Intercambio*",Tabla1[Universidad KPIs],'Utilización Convenios'!$C71,Tabla1[Año de Movilidad],'Utilización Convenios'!G$3,Tabla1[Nivel],"Pregrado") -> 0 | H71: =COUNTIFS(Tabla2[Tipo de Movilidad],"Intercambio*",Tabla2[Universidad KPIs],'Utilización Convenios'!$C71,Tabla2[Año],'Utilización Convenios'!G$3,Tabla2[Nivel Nominación],"Undergraduate / Bachelor") -> 0 | I71: =COUNTIFS(Tabla1[Tipo de Movilidad],"Intercambio*",Tabla1[Universidad KPIs],'Utilización Convenios'!$C71,Tabla1[Año de Movilidad],'Utilización Convenios'!I$3,Tabla1[Nivel],"Pregrado") -> 0 | J71: =COUNTIFS(Tabla2[Tipo de Movilidad],"Intercambio*",Tabla2[Universidad KPIs],'Utilización Convenios'!$C71,Tabla2[Año],'Utilización Convenios'!I$3,Tabla2[Nivel Nominación],"Undergraduate / Bachelor") -> 0 | K71: =COUNTIFS(Tabla1[Tipo de Movilidad],"Intercambio*",Tabla1[Universidad KPIs],'Utilización Convenios'!$C71,Tabla1[Año de Movilidad],'Utilización Convenios'!K$3,Tabla1[Nivel],"Pregrado") -> 1 | L71: =COUNTIFS(Tabla2[Tipo de Movilidad],"Intercambio*",Tabla2[Universidad KPIs],'Utilización Convenios'!$C71,Tabla2[Año],'Utilización Convenios'!K$3,Tabla2[Nivel Nominación],"Undergraduate / Bachelor") -> 0 | M71: =COUNTIFS(Tabla1[Tipo de Movilidad],"Intercambio*",Tabla1[Universidad KPIs],'Utilización Convenios'!$C71,Tabla1[Año de Movilidad],'Utilización Convenios'!M$3,Tabla1[Nivel],"Pregrado") -> 0 | N71: =COUNTIFS(Tabla2[Tipo de Movilidad],"Intercambio*",Tabla2[Universidad KPIs],'Utilización Convenios'!$C71,Tabla2[Año],'Utilización Convenios'!M$3,Tabla2[Nivel Nominación],"Undergraduate / Bachelor") -> 0 | O71: =COUNTIFS(Tabla1[Tipo de Movilidad],"Intercambio*",Tabla1[Universidad KPIs],'Utilización Convenios'!$C71,Tabla1[Año de Movilidad],'Utilización Convenios'!O$3,Tabla1[Nivel],"Pregrado") -> 1 | P71: =COUNTIFS(Tabla2[Tipo de Movilidad],"Intercambio*",Tabla2[Universidad KPIs],'Utilización Convenios'!$C71,Tabla2[Año],'Utilización Convenios'!O$3,Tabla2[Nivel Nominación],"Undergraduate / Bachelor") -> 0 | Q71: =SUMIF($E$4:$P$4,Q$4,$E71:$P71) -> 2 | R71: =SUMIF($E$4:$P$4,R$4,$E71:$P71) -> 1
